Workbook

Sheet Raw data
A1: 발주일자 | B1: 업체코드 | C1: 업체명 | D1: 점포코드 | E1: 점포명 | F1: 상품코드 | G1: 상품명 | H1: 발주원가 | I1: 발주단위 | J1: LOT | K1: 수량 | L1: 발주금액 | M1: 전표번호 | N1: 바이어명 | O1: 센터입하일자 | P1: 센터코드 | Q1: 점입점일자 | R1: 납품구분 | S1: 기타(점코드) | T1: 기타(점포명) | U1: 점포명
A2: 20260326 | B2: 1368001 | C2: 맨소래덤아시아퍼시픽 주식회사 | D2: 2017 | E2: TR스타필드부천점 | F2: 8809020344895 | G2: 하다라보 고쿠쥰 로션 170ml*2입 | H2: 11655 | I2: 12 | J2: 12 | K2: 144 | L2: 1678320 | M2: 1278300779 | N2: 최철원 | O2: 20260327 | P2: 9150 | Q2: 평택DRY센터 | R2: 20260327 | S2: TC | T2: 2017 | U2: TR스타필드부천점 | AA2: 매장 창고
A3: 20260326 | B3: 1368001 | C3: 맨소래덤아시아퍼시픽 주식회사 | D3: 2017 | E3: TR스타필드부천점 | F3: 8809020344901 | G3: 하다라보 고쿠쥰 밀크 140ml*2입 | H3: 12784 | I3: 12 | J3: 12 | K3: 144 | L3: 1840896 | M3: 1278300779 | N3: 최철원 | O3: 20260327 | P3: 9150 | Q3: 평택DRY센터 | R3: 20260327 | S3: TC | T3: 2017 | U3: TR스타필드부천점 | AA3: 매장 창고
A4: 20260326 | B4: 1368001 | C4: 맨소래덤아시아퍼시픽 주식회사 | D4: 2010 | E4: TR일산점 | F4: 8809020344895 | G4: 하다라보 고쿠쥰 로션 170ml*2입 | H4: 11655 | I4: 12 | J4: 12 | K4: 144 | L4: 1678320 | M4: 1278300870 | N4: 최철원 | O4: 20260327 | P4: 9150 | Q4: 평택DRY센터 | R4: 20260327 | S4: TC | T4: 2010 | U4: TR일산점 | AA4: 매장 창고
A5: 20260326 | B5: 1368001 | C5: 맨소래덤아시아퍼시픽 주식회사 | D5: 2008 | E5: TR양산점 | F5: 8809020344895 | G5: 하다라보 고쿠쥰 로션 170ml*2입 | H5: 11655 | I5: 12 | J5: 12 | K5: 144 | L5: 1678320 | M5: 1278300871 | N5: 최철원 | O5: 20260327 | P5: 9102 | Q5: 칠곡DRY센터 | R5: 20260327 | S5: TC | T5: 2008 | U5: TR양산점 | AA5: 매장 창고
A6: 20260326 | B6: 1368001 | C6: 맨소래덤아시아퍼시픽 주식회사 | D6: 2008 | E6: TR양산점 | F6: 8809020344901 | G6: 하다라보 고쿠쥰 밀크 140ml*2입 | H6: 12784 | I6: 12 | J6: 12 | K6: 144 | L6: 1840896 | M6: 1278300871 | N6: 최철원 | O6: 20260327 | P6: 9102 | Q6: 칠곡DRY센터 | R6: 20260327 | S6: TC | T6: 2008 | U6: TR양산점 | AA6: 매장 창고
A7: 20260326 | B7: 1368001 | C7: 맨소래덤아시아퍼시픽 주식회사 | D7: 2005 | E7: TR비산점 | F7: 8809020344901 | G7: 하다라보 고쿠쥰 밀크 140ml*2입 | H7: 12784 | I7: 12 | J7: 12 | K7: 144 | L7: 1840896 | M7: 1278300956 | N7: 최철원 | O7: 20260327 | P7: 9102 | Q7: 칠곡DRY센터 | R7: 20260327 | S7: TC | T7: 2005 | U7: TR비산점 | AA7: 매장 창고
A8: 20260326 | B8: 1368001 | C8: 맨소래덤아시아퍼시픽 주식회사 | D8: 2011 | E8: TR스타필드하남점 | F8: 8809020344901 | G8: 하다라보 고쿠쥰 밀크 140ml*2입 | H8: 12784 | I8: 12 | J8: 12 | K8: 144 | L8: 1840896 | M8: 1278300957 | N8: 최철원 | O8: 20260327 | P8: 9150 | Q8: 평택DRY센터 | R8: 20260327 | S8: TC | T8: 2011 | U8: TR스타필드하남점 | AA8: 매장 창고
A9: 20260326 | B9: 1368001 | C9: 맨소래덤아시아퍼시픽 주식회사 | D9: 2023 | E9: TR마곡점 | F9: 8809020344901 | G9: 하다라보 고쿠쥰 밀크 140ml*2입 | H9: 12784 | I9: 12 | J9: 12 | K9: 144 | L9: 1840896 | M9: 1278300958 | N9: 최철원 | O9: 20260327 | P9: 9150 | Q9: 평택DRY센터 | R9: 20260327 | S9: TC | T9: 2023 | U9: TR마곡점 | AA9: 매장 창고
A10: 20260326 | B10: 1368001 | C10: 맨소래덤아시아퍼시픽 주식회사 | D10: 2009 | E10: TR수원점 | F10: 8809020344901 | G10: 하다라보 고쿠쥰 밀크 140ml*2입 | H10: 12784 | I10: 12 | J10: 12 | K10: 144 | L10: 1840896 | M10: 1278301232 | N10: 최철원 | O10: 20260327 | P10: 9150 | Q10: 평택DRY센터 | R10: 20260327 | S10: TC | T10: 2009 | U10: TR수원점 | AA10: 매장 창고
A11: 20260326 | B11: 1368001 | C11: 맨소래덤아시아퍼시픽 주식회사 | D11: 2022 | E11: TR스타필드수원화서점 | F11: 8809020344901 | G11: 하다라보 고쿠쥰 밀크 140ml*2입 | H11: 12784 | I11: 12 | J11: 12 | K11: 144 | L11: 1840896 | M11: 1278301233 | N11: 최철원 | O11: 20260327 | P11: 9150 | Q11: 평택DRY센터 | R11: 20260327 | S11: TC | T11: 2022 | U11: TR스타필드수원화서점 | AA11: 매장 창고
A12: 20260326 | B12: 1368001 | C12: 맨소래덤아시아퍼시픽 주식회사 | D12: 2020 | E12: TR연산점 | F12: 8809020344901 | G12: 하다라보 고쿠쥰 밀크 140ml*2입 | H12: 12784 | I12: 12 | J12: 12 | K12: 144 | L12: 1840896 | M12: 1278301234 | N12: 최철원 | O12: 20260327 | P12: 9102 | Q12: 칠곡DRY센터 | R12: 20260327 | S12: TC | T12: 2020 | U12: TR연산점 | AA12: 매장 창고
A13: 20260326 | B13: 1368001 | C13: 맨소래덤아시아퍼시픽 주식회사 | D13: 2003 | E13: TR월평점 | F13: 8809020344895 | G13: 하다라보 고쿠쥰 로션 170ml*2입 | H13: 11655 | I13: 12 | J13: 12 | K13: 144 | L13: 1678320 | M13: 1278301235 | N13: 최철원 | O13: 20260327 | P13: 9150 | Q13: 평택DRY센터 | R13: 20260327 | S13: TC | T13: 2003 | U13: TR월평점 | AA13: 매장 창고
A14: 20260326 | B14: 1368001 | C14: 맨소래덤아시아퍼시픽 주식회사 | D14: 2003 | E14: TR월평점 | F14: 8809020344901 | G14: 하다라보 고쿠쥰 밀크 140ml*2입 | H14: 12784 | I14: 12 | J14: 12 | K14: 144 | L14: 1840896 | M14: 1278301235 | N14: 최철원 | O14: 20260327 | P14: 9150 | Q14: 평택DRY센터 | R14: 20260327 | S14: TC | T14: 2003 | U14: TR월평점 | AA14: 매장 창고

Sheet Summary(수주업로드용)
A1: 납품일자 | B1: 발주코드 | D1: 배송코드 | E1: 센터명 | F1: 상품코드 | G1: 제품명 | H1: UNIT수량 | I1: UNIT단가 | J1: Total Amount | K1: LOT | L1: 점포명
A2: ='Raw data'!O2 -> 20260327 | B2: 81011010 | D2: =VLOOKUP('Raw data'!P2,'점포코드 '!A:B,2,0) -> 81033036 | E2: =VLOOKUP(D2,'점포코드 '!B:C,2,0) -> 평택 | F2: =VLOOKUP('Raw data'!F2,제품명!C:D,2,0) -> ME90621L3L | G2: =VLOOKUP(F2,제품명!D:E,2,0) -> 하다라보 고쿠쥰 로션 170ml*2입 | H2: ='Raw data'!K2 -> 144 | I2: ='Raw data'!H2 -> 11655 | J2: =H2*I2 -> 1678320 | L2: ='Raw data'!U2 -> TR스타필드부천점 | M2: 점포확인
A3: ='Raw data'!O3 -> 20260327 | B3: 81011010 | D3: =VLOOKUP('Raw data'!P3,'점포코드 '!A:B,2,0) -> 81033036 | E3: =VLOOKUP(D3,'점포코드 '!B:C,2,0) -> 평택 | F3: =VLOOKUP('Raw data'!F3,제품명!C:D,2,0) -> ME90621M3M | G3: =VLOOKUP(F3,제품명!D:E,2,0) -> 하다라보 고쿠쥰 밀크 140ml*2입 | H3: ='Raw data'!K3 -> 144 | I3: ='Raw data'!H3 -> 12784 | J3: =H3*I3 -> 1840896 | L3: ='Raw data'!U3 -> TR스타필드부천점 | M3: 점포확인
A4: ='Raw data'!O4 -> 20260327 | B4: 81011010 | D4: =VLOOKUP('Raw data'!P4,'점포코드 '!A:B,2,0) -> 81033036 | E4: =VLOOKUP(D4,'점포코드 '!B:C,2,0) -> 평택 | F4: =VLOOKUP('Raw data'!F4,제품명!C:D,2,0) -> ME90621L3L | G4: =VLOOKUP(F4,제품명!D:E,2,0) -> 하다라보 고쿠쥰 로션 170ml*2입 | H4: ='Raw data'!K4 -> 144 | I4: ='Raw data'!H4 -> 11655 | J4: =H4*I4 -> 1678320 | L4: ='Raw data'!U4 -> TR일산점 | M4: 점포확인
A5: ='Raw data'!O5 -> 20260327 | B5: 81011010 | D5: =VLOOKUP('Raw data'!P5,'점포코드 '!A:B,2,0) -> 89011174 | E5: =VLOOKUP(D5,'점포코드 '!B:C,2,0) -> 대구 | F5: =VLOOKUP('Raw data'!F5,제품명!C:D,2,0) -> ME90621L3L | G5: =VLOOKUP(F5,제품명!D:E,2,0) -> 하다라보 고쿠쥰 로션 170ml*2입 | H5: ='Raw data'!K5 -> 144 | I5: ='Raw data'!H5 -> 11655 | J5: =H5*I5 -> 1678320 | L5: ='Raw data'!U5 -> TR양산점 | M5: 점포확인
A6: ='Raw data'!O6 -> 20260327 | B6: 81011010 | D6: =VLOOKUP('Raw data'!P6,'점포코드 '!A:B,2,0) -> 89011174 | E6: =VLOOKUP(D6,'점포코드 '!B:C,2,0) -> 대구 | F6: =VLOOKUP('Raw data'!F6,제품명!C:D,2,0) -> ME90621M3M | G6: =VLOOKUP(F6,제품명!D:E,2,0) -> 하다라보 고쿠쥰 밀크 140ml*2입 | H6: ='Raw data'!K6 -> 144 | I6: ='Raw data'!H6 -> 12784 | J6: =H6*I6 -> 1840896 | L6: ='Raw data'!U6 -> TR양산점 | M6: 점포확인
A7: ='Raw data'!O7 -> 20260327 | B7: 81011010 | D7: =VLOOKUP('Raw data'!P7,'점포코드 '!A:B,2,0) -> 89011174 | E7: =VLOOKUP(D7,'점포코드 '!B:C,2,0) -> 대구 | F7: =VLOOKUP('Raw data'!F7,제품명!C:D,2,0) -> ME90621M3M | G7: =VLOOKUP(F7,제품명!D:E,2,0) -> 하다라보 고쿠쥰 밀크 140ml*2입 | H7: ='Raw data'!K7 -> 144 | I7: ='Raw data'!H7 -> 12784 | J7: =H7*I7 -> 1840896 | L7: ='Raw data'!U7 -> TR비산점 | M7: 점포확인
A8: ='Raw data'!O8 -> 20260327 | B8: 81011010 | D8: =VLOOKUP('Raw data'!P8,'점포코드 '!A:B,2,0) -> 81033036 | E8: =VLOOKUP(D8,'점포코드 '!B:C,2,0) -> 평택 | F8: =VLOOKUP('Raw data'!F8,제품명!C:D,2,0) -> ME90621M3M | G8: =VLOOKUP(F8,제품명!D:E,2,0) -> 하다라보 고쿠쥰 밀크 140ml*2입 | H8: ='Raw data'!K8 -> 144 | I8: ='Raw data'!H8 -> 12784 | J8: =H8*I8 -> 1840896 | L8: ='Raw data'!U8 -> TR스타필드하남점 | M8: 점포확인
A9: ='Raw data'!O9 -> 20260327 | B9: 81011010 | D9: =VLOOKUP('Raw data'!P9,'점포코드 '!A:B,2,0) -> 81033036 | E9: =VLOOKUP(D9,'점포코드 '!B:C,2,0) -> 평택 | F9: =VLOOKUP('Raw data'!F9,제품명!C:D,2,0) -> ME90621M3M | G9: =VLOOKUP(F9,제품명!D:E,2,0) -> 하다라보 고쿠쥰 밀크 140ml*2입 | H9: ='Raw data'!K9 -> 144 | I9: ='Raw data'!H9 -> 12784 | J9: =H9*I9 -> 1840896 | L9: ='Raw data'!U9 -> TR마곡점 | M9: 점포확인
A10: ='Raw data'!O10 -> 20260327 | B10: 81011010 | D10: =VLOOKUP('Raw data'!P10,'점포코드 '!A:B,2,0) -> 81033036 | E10: =VLOOKUP(D10,'점포코드 '!B:C,2,0) -> 평택 | F10: =VLOOKUP('Raw data'!F10,제품명!C:D,2,0) -> ME90621M3M | G10: =VLOOKUP(F10,제품명!D:E,2,0) -> 하다라보 고쿠쥰 밀크 140ml*2입 | H10: ='Raw data'!K10 -> 144 | I10: ='Raw data'!H10 -> 12784 | J10: =H10*I10 -> 1840896 | L10: ='Raw data'!U10 -> TR수원점 | M10: 점포확인
A11: ='Raw data'!O11 -> 20260327 | B11: 81011010 | D11: =VLOOKUP('Raw data'!P11,'점포코드 '!A:B,2,0) -> 81033036 | E11: =VLOOKUP(D11,'점포코드 '!B:C,2,0) -> 평택 | F11: =VLOOKUP('Raw data'!F11,제품명!C:D,2,0) -> ME90621M3M | G11: =VLOOKUP(F11,제품명!D:E,2,0) -> 하다라보 고쿠쥰 밀크 140ml*2입 | H11: ='Raw data'!K11 -> 144 | I11: ='Raw data'!H11 -> 12784 | J11: =H11*I11 -> 1840896 | L11: ='Raw data'!U11 -> TR스타필드수원화서점 | M11: 점포확인
A12: ='Raw data'!O12 -> 20260327 | B12: 81011010 | D12: =VLOOKUP('Raw data'!P12,'점포코드 '!A:B,2,0) -> 89011174 | E12: =VLOOKUP(D12,'점포코드 '!B:C,2,0) -> 대구 | F12: =VLOOKUP('Raw data'!F12,제품명!C:D,2,0) -> ME90621M3M | G12: =VLOOKUP(F12,제품명!D:E,2,0) -> 하다라보 고쿠쥰 밀크 140ml*2입 | H12: ='Raw data'!K12 -> 144 | I12: ='Raw data'!H12 -> 12784 | J12: =H12*I12 -> 1840896 | L12: ='Raw data'!U12 -> TR연산점 | M12: 점포확인
A13: ='Raw data'!O13 -> 20260327 | B13: 81011010 | D13: =VLOOKUP('Raw data'!P13,'점포코드 '!A:B,2,0) -> 81033036 | E13: =VLOOKUP(D13,'점포코드 '!B:C,2,0) -> 평택 | F13: =VLOOKUP('Raw data'!F13,제품명!C:D,2,0) -> ME90621L3L | G13: =VLOOKUP(F13,제품명!D:E,2,0) -> 하다라보 고쿠쥰 로션 170ml*2입 | H13: ='Raw data'!K13 -> 144 | I13: ='Raw data'!H13 -> 11655 | J13: =H13*I13 -> 1678320 | L13: ='Raw data'!U13 -> TR월평점 | M13: 점포확인
... A35: ='Raw data'!O35 -> 0 | B35: 81011010 | D35: =VLOOKUP('Raw data'!P35,'점포코드 '!A:B,2,0) -> #N/A | E35: =VLOOKUP(D35,'점포코드 '!B:C,2,0) -> #N/A | F35: =VLOOKUP('Raw data'!F35,제품명!C:D,2,0) -> #N/A | G35: =VLOOKUP(F35,제품명!D:E,2,0) -> #N/A | H35: ='Raw data'!K35 -> 0 | I35: ='Raw data'!H35 -> 0 | J35: =H35*I35 -> 0 | L35: ='Raw data'!U35 -> 0 | M35: 점포확인
A36: ='Raw data'!O36 -> 0 | B36: 81011010 | D36: =VLOOKUP('Raw data'!P36,'점포코드 '!A:B,2,0) -> #N/A | E36: =VLOOKUP(D36,'점포코드 '!B:C,2,0) -> #N/A | F36: =VLOOKUP('Raw data'!F36,제품명!C:D,2,0) -> #N/A | G36: =VLOOKUP(F36,제품명!D:E,2,0) -> #N/A | H36: ='Raw data'!K36 -> 0 | I36: ='Raw data'!H36 -> 0 | J36: =H36*I36 -> 0 | L36: ='Raw data'!U36 -> 0
A37: ='Raw data'!O37 -> 0 | B37: 81011010 | D37: =VLOOKUP('Raw data'!P37,'점포코드 '!A:B,2,0) -> #N/A | E37: =VLOOKUP(D37,'점포코드 '!B:C,2,0) -> #N/A | F37: =VLOOKUP('Raw data'!F37,제품명!C:D,2,0) -> #N/A | G37: =VLOOKUP(F37,제품명!D:E,2,0) -> #N/A | H37: ='Raw data'!K37 -> 0 | I37: ='Raw data'!H37 -> 0 | J37: =H37*I37 -> 0 | L37: ='Raw data'!U37 -> 0
A38: ='Raw data'!O38 -> 0 | B38: 81011010 | D38: =VLOOKUP('Raw data'!P38,'점포코드 '!A:B,2,0) -> #N/A | E38: =VLOOKUP(D38,'점포코드 '!B:C,2,0) -> #N/A | F38: =VLOOKUP('Raw data'!F38,제품명!C:D,2,0) -> #N/A | G38: =VLOOKUP(F38,제품명!D:E,2,0) -> #N/A | H38: ='Raw data'!K38 -> 0 | I38: ='Raw data'!H38 -> 0 | J38: =H38*I38 -> 0 | L38: ='Raw data'!U38 -> 0
A39: ='Raw data'!O39 -> 0 | B39: 81011010 | D39: =VLOOKUP('Raw data'!P39,'점포코드 '!A:B,2,0) -> #N/A | E39: =VLOOKUP(D39,'점포코드 '!B:C,2,0) -> #N/A | F39: =VLOOKUP('Raw data'!F39,제품명!C:D,2,0) -> #N/A | G39: =VLOOKUP(F39,제품명!D:E,2,0) -> #N/A | H39: ='Raw data'!K39 -> 0 | I39: ='Raw data'!H39 -> 0 | J39: =H39*I39 -> 0 | L39: ='Raw data'!U39 -> 0
A40: ='Raw data'!O40 -> 0 | B40: 81011010 | D40: =VLOOKUP('Raw data'!P40,'점포코드 '!A:B,2,0) -> #N/A | E40: =VLOOKUP(D40,'점포코드 '!B:C,2,0) -> #N/A | F40: =VLOOKUP('Raw data'!F40,제품명!C:D,2,0) -> #N/A | G40: =VLOOKUP(F40,제품명!D:E,2,0) -> #N/A | H40: ='Raw data'!K40 -> 0 | I40: ='Raw data'!H40 -> 0 | J40: =H40*I40 -> 0 | L40: ='Raw data'!U40 -> 0
A41: ='Raw data'!O41 -> 0 | B41: 81011010 | D41: =VLOOKUP('Raw data'!P41,'점포코드 '!A:B,2,0) -> #N/A | E41: =VLOOKUP(D41,'점포코드 '!B:C,2,0) -> #N/A | F41: =VLOOKUP('Raw data'!F41,제품명!C:D,2,0) -> #N/A | G41: =VLOOKUP(F41,제품명!D:E,2,0) -> #N/A | H41: ='Raw data'!K41 -> 0 | I41: ='Raw data'!H41 -> 0 | J41: =H41*I41 -> 0 | L41: ='Raw data'!U41 -> 0
A42: ='Raw data'!O42 -> 0 | B42: 81011010 | D42: =VLOOKUP('Raw data'!P42,'점포코드 '!A:B,2,0) -> #N/A | E42: =VLOOKUP(D42,'점포코드 '!B:C,2,0) -> #N/A | F42: =VLOOKUP('Raw data'!F42,제품명!C:D,2,0) -> #N/A | G42: =VLOOKUP(F42,제품명!D:E,2,0) -> #N/A | H42: ='Raw data'!K42 -> 0 | I42: ='Raw data'!H42 -> 0 | J42: =H42*I42 -> 0 | L42: ='Raw data'!U42 -> 0
A43: ='Raw data'!O43 -> 0 | D43: =VLOOKUP('Raw data'!P43,'점포코드 '!A:B,2,0) -> #N/A | E43: =VLOOKUP(D43,'점포코드 '!B:C,2,0) -> #N/A | F43: =VLOOKUP('Raw data'!F43,제품명!C:D,2,0) -> #N/A | G43: =VLOOKUP(F43,제품명!D:E,2,0) -> #N/A | H43: ='Raw data'!K43 -> 0 | I43: ='Raw data'!H43 -> 0 | J43: =H43*I43 -> 0
A44: ='Raw data'!O44 -> 0 | D44: =VLOOKUP('Raw data'!P44,'점포코드 '!A:B,2,0) -> #N/A | E44: =VLOOKUP(D44,'점포코드 '!B:C,2,0) -> #N/A | F44: =VLOOKUP('Raw data'!F44,제품명!C:D,2,0) -> #N/A | G44: =VLOOKUP(F44,제품명!D:E,2,0) -> #N/A | H44: ='Raw data'!K44 -> 0 | I44: ='Raw data'!H44 -> 0 | J44: =H44*I44 -> 0
A45: ='Raw data'!O45 -> 0 | D45: =VLOOKUP('Raw data'!P45,'점포코드 '!A:B,2,0) -> #N/A | E45: =VLOOKUP(D45,'점포코드 '!B:C,2,0) -> #N/A | F45: =VLOOKUP('Raw data'!F45,제품명!C:D,2,0) -> #N/A | G45: =VLOOKUP(F45,제품명!D:E,2,0) -> #N/A | H45: ='Raw data'!K45 -> 0 | I45: ='Raw data'!H45 -> 0 | J45: =H45*I45 -> 0
A46: ='Raw data'!O46 -> 0 | D46: =VLOOKUP('Raw data'!P46,'점포코드 '!A:B,2,0) -> #N/A | E46: =VLOOKUP(D46,'점포코드 '!B:C,2,0) -> #N/A | F46: =VLOOKUP('Raw data'!F46,제품명!C:D,2,0) -> #N/A | G46: =VLOOKUP(F46,제품명!D:E,2,0) -> #N/A | H46: ='Raw data'!K46 -> 0 | I46: ='Raw data'!H46 -> 0 | J46: =H46*I46 -> 0
A47: ='Raw data'!O47 -> 0 | D47: =VLOOKUP('Raw data'!P47,'점포코드 '!A:B,2,0) -> #N/A | E47: =VLOOKUP(D47,'점포코드 '!B:C,2,0) -> #N/A | F47: =VLOOKUP('Raw data'!F47,제품명!C:D,2,0) -> #N/A | G47: =VLOOKUP(F47,제품명!D:E,2,0) -> #N/A | H47: ='Raw data'!K47 -> 0 | I47: ='Raw data'!H47 -> 0 | J47: =H47*I47 -> 0
A48: ='Raw data'!O48 -> 0 | D48: =VLOOKUP('Raw data'!P48,'점포코드 '!A:B,2,0) -> #N/A | E48: =VLOOKUP(D48,'점포코드 '!B:C,2,0) -> #N/A | F48: =VLOOKUP('Raw data'!F48,제품명!C:D,2,0) -> #N/A | G48: =VLOOKUP(F48,제품명!D:E,2,0) -> #N/A | H48: ='Raw data'!K48 -> 0 | I48: ='Raw data'!H48 -> 0 | J48: =H48*I48 -> 0
A49: ='Raw data'!O49 -> 0 | D49: =VLOOKUP('Raw data'!P49,'점포코드 '!A:B,2,0) -> #N/A | E49: =VLOOKUP(D49,'점포코드 '!B:C,2,0) -> #N/A | F49: =VLOOKUP('Raw data'!F49,제품명!C:D,2,0) -> #N/A | G49: =VLOOKUP(F49,제품명!D:E,2,0) -> #N/A | H49: ='Raw data'!K49 -> 0 | I49: ='Raw data'!H49 -> 0 | J49: =H49*I49 -> 0
A50: ='Raw data'!O50 -> 0 | D50: =VLOOKUP('Raw data'!P50,'점포코드 '!A:B,2,0) -> #N/A | E50: =VLOOKUP(D50,'점포코드 '!B:C,2,0) -> #N/A | F50: =VLOOKUP('Raw data'!F50,제품명!C:D,2,0) -> #N/A | G50: =VLOOKUP(F50,제품명!D:E,2,0) -> #N/A | H50: ='Raw data'!K50 -> 0 | I50: ='Raw data'!H50 -> 0 | J50: =H50*I50 -> 0
A51: ='Raw data'!O51 -> 0 | D51: =VLOOKUP('Raw data'!P51,'점포코드 '!A:B,2,0) -> #N/A | E51: =VLOOKUP(D51,'점포코드 '!B:C,2,0) -> #N/A | F51: =VLOOKUP('Raw data'!F51,제품명!C:D,2,0) -> #N/A | G51: =VLOOKUP(F51,제품명!D:E,2,0) -> #N/A | H51: ='Raw data'!K51 -> 0 | I51: ='Raw data'!H51 -> 0 | J51: =H51*I51 -> 0
A52: ='Raw data'!O52 -> 0 | D52: =VLOOKUP('Raw data'!P52,'점포코드 '!A:B,2,0) -> #N/A | E52: =VLOOKUP(D52,'점포코드 '!B:C,2,0) -> #N/A | F52: =VLOOKUP('Raw data'!F52,제품명!C:D,2,0) -> #N/A | G52: =VLOOKUP(F52,제품명!D:E,2,0) -> #N/A | H52: ='Raw data'!K52 -> 0 | I52: ='Raw data'!H52 -> 0 | J52: =H52*I52 -> 0
A53: ='Raw data'!O53 -> 0 | D53: =VLOOKUP('Raw data'!P53,'점포코드 '!A:B,2,0) -> #N/A | E53: =VLOOKUP(D53,'점포코드 '!B:C,2,0) -> #N/A | F53: =VLOOKUP('Raw data'!F53,제품명!C:D,2,0) -> #N/A | G53: =VLOOKUP(F53,제품명!D:E,2,0) -> #N/A | H53: ='Raw data'!K53 -> 0 | I53: ='Raw data'!H53 -> 0 | J53: =H53*I53 -> 0
A54: ='Raw data'!O54 -> 0 | D54: =VLOOKUP('Raw data'!P54,'점포코드 '!A:B,2,0) -> #N/A | E54: =VLOOKUP(D54,'점포코드 '!B:C,2,0) -> #N/A | F54: =VLOOKUP('Raw data'!F54,제품명!C:D,2,0) -> #N/A | G54: =VLOOKUP(F54,제품명!D:E,2,0) -> #N/A | H54: ='Raw data'!K54 -> 0 | I54: ='Raw data'!H54 -> 0 | J54: =H54*I54 -> 0
... A256: ='Raw data'!O256 -> 0 | D256: =VLOOKUP('Raw data'!P256,'점포코드 '!A:B,2,0) -> #N/A | E256: =VLOOKUP(D256,'점포코드 '!B:C,2,0) -> #N/A | F256: =VLOOKUP('Raw data'!F256,제품명!C:D,2,0) -> #N/A | G256: =VLOOKUP(F256,제품명!D:E,2,0) -> #N/A | H256: ='Raw data'!K256 -> 0 | I256: ='Raw data'!H256 -> 0 | J256: =H256*I256 -> 0
G263: 롤온
G264: 포밍
G265: 밀크
G266: 로션 | N266: ※트레이더스 유통기한 입점 기준
N267: - 국내 제조 : 총 유통기한의 2/3
N268: - 수입 상품 : 총 유통기한의 1/2
...

Sheet Sheet1
A1: 배송코드 | B1: 센터명 | C1: 상품코드 | D1: 제품명 | E1: UNIT수량 | F1: UNIT단가 | G1: Total Amount | H1: LOT | I1: 점포명
A2: 81033036 | B2: 평택 | C2: ME90621L3L | D2: 하다라보 고쿠쥰 로션 170ml*2입 | E2: 144 | F2: 11655 | G2: 1678320 | I2: TR스타필드부천점
A3: 81033036 | B3: 평택 | C3: ME90621M3M | D3: 하다라보 고쿠쥰 밀크 140ml*2입 | E3: 144 | F3: 12784 | G3: 1840896 | I3: TR스타필드부천점
A4: 81033036 | B4: 평택 | C4: ME90621L3L | D4: 하다라보 고쿠쥰 로션 170ml*2입 | E4: 144 | F4: 11655 | G4: 1678320 | I4: TR일산점
A5: 89011174 | B5: 대구 | C5: ME90621L3L | D5: 하다라보 고쿠쥰 로션 170ml*2입 | E5: 144 | F5: 11655 | G5: 1678320 | I5: TR양산점
A6: 89011174 | B6: 대구 | C6: ME90621M3M | D6: 하다라보 고쿠쥰 밀크 140ml*2입 | E6: 144 | F6: 12784 | G6: 1840896 | I6: TR양산점
A7: 89011174 | B7: 대구 | C7: ME90621M3M | D7: 하다라보 고쿠쥰 밀크 140ml*2입 | E7: 144 | F7: 12784 | G7: 1840896 | I7: TR비산점
A8: 81033036 | B8: 평택 | C8: ME90621M3M | D8: 하다라보 고쿠쥰 밀크 140ml*2입 | E8: 144 | F8: 12784 | G8: 1840896 | I8: TR스타필드하남점
A9: 81033036 | B9: 평택 | C9: ME90621M3M | D9: 하다라보 고쿠쥰 밀크 140ml*2입 | E9: 144 | F9: 12784 | G9: 1840896 | I9: TR마곡점
A10: 81033036 | B10: 평택 | C10: ME90621M3M | D10: 하다라보 고쿠쥰 밀크 140ml*2입 | E10: 144 | F10: 12784 | G10: 1840896 | I10: TR수원점
A11: 81033036 | B11: 평택 | C11: ME90621M3M | D11: 하다라보 고쿠쥰 밀크 140ml*2입 | E11: 144 | F11: 12784 | G11: 1840896 | I11: TR스타필드수원화서점
A12: 89011174 | B12: 대구 | C12: ME90621M3M | D12: 하다라보 고쿠쥰 밀크 140ml*2입 | E12: 144 | F12: 12784 | G12: 1840896 | I12: TR연산점
A13: 81033036 | B13: 평택 | C13: ME90621L3L | D13: 하다라보 고쿠쥰 로션 170ml*2입 | E13: 144 | F13: 11655 | G13: 1678320 | I13: TR월평점
A14: 81033036 | B14: 평택 | C14: ME90621M3M | D14: 하다라보 고쿠쥰 밀크 140ml*2입 | E14: 144 | F14: 12784 | G14: 1840896 | I14: TR월평점

Sheet Sheet2
A3: 배송코드 | B3: 센터명 | C3: 점포명 | D3: 상품코드 | E3: 제품명 | F3: 합계 : UNIT수량
A4: 89011174 | B4: 대구 | C4: TR양산점 | D4: ME90621L3L | E4: 하다라보 고쿠쥰 로션 170ml*2입 | F4: 144
A5: 89011174 | B5: 대구 | C5: TR양산점 | D5: ME90621M3M | E5: 하다라보 고쿠쥰 밀크 140ml*2입 | F5: 144
A6: 89011174 | B6: 대구 | C6: TR비산점 | D6: ME90621M3M | E6: 하다라보 고쿠쥰 밀크 140ml*2입 | F6: 144
A7: 89011174 | B7: 대구 | C7: TR연산점 | D7: ME90621M3M | E7: 하다라보 고쿠쥰 밀크 140ml*2입 | F7: 144
A8: (비어 있음) | B8: (비어 있음) | C8: (비어 있음) | D8: (비어 있음) | E8: (비어 있음)
A9: 81033036 | B9: 평택 | C9: TR수원점 | D9: ME90621M3M | E9: 하다라보 고쿠쥰 밀크 140ml*2입 | F9: 144
A10: 81033036 | B10: 평택 | C10: TR스타필드부천점 | D10: ME90621L3L | E10: 하다라보 고쿠쥰 로션 170ml*2입 | F10: 144
A11: 81033036 | B11: 평택 | C11: TR스타필드부천점 | D11: ME90621M3M | E11: 하다라보 고쿠쥰 밀크 140ml*2입 | F11: 144
A12: 81033036 | B12: 평택 | C12: TR스타필드수원화서점 | D12: ME90621M3M | E12: 하다라보 고쿠쥰 밀크 140ml*2입 | F12: 144
A13: 81033036 | B13: 평택 | C13: TR스타필드하남점 | D13: ME90621M3M | E13: 하다라보 고쿠쥰 밀크 140ml*2입 | F13: 144
A14: 81033036 | B14: 평택 | C14: TR월평점 | D14: ME90621L3L | E14: 하다라보 고쿠쥰 로션 170ml*2입 | F14: 144
A15: 81033036 | B15: 평택 | C15: TR월평점 | D15: ME90621M3M | E15: 하다라보 고쿠쥰 밀크 140ml*2입 | F15: 144
A16: 81033036 | B16: 평택 | C16: TR마곡점 | D16: ME90621M3M | E16: 하다라보 고쿠쥰 밀크 140ml*2입 | F16: 144
A17: 81033036 | B17: 평택 | C17: TR일산점 | D17: ME90621L3L | E17: 하다라보 고쿠쥰 로션 170ml*2입 | F17: 144
A18: 총합계 | F18: 1872

Sheet 점포코드 
A2: 점포명 | B2: 점포코드
A3: 9150 | B3: 81033036 | C3: 평택
A4: 9102 | B4: 89011174 | C4: 대구
A5: 9120 | B5: 81011012 | C5: 여주

Sheet 제품명
A1: BRAND | B1: 이마트 상품명 | C1: 바코드 | D1: 상품코드(기획) | E1: 상품명(기획) | F1: 원래코드 | G1: 비고 | H1: REGUAL
B2: 아크네스 포밍워시 200ml*2입 | C2: 8809020340941 | D2: ME00621C44 | E2: 아크네스 포밍워시 200ml*2입 | F2: ME00621C44
B3: 하다라보 고쿠쥰 라이트 로션 170ml*2입 | C3: 8809020340965 | D3: ME00621GL7 | E3: 하다라보 고쿠쥰 라이트 로션 170ml*2입 | F3: ME00621GL7
B4: 하다라보 고쿠쥰 밀크 1+1 (트레이더스) | C4: 8809020341245 | D4: ME00621H56 | E4: 하다라보 고쿠쥰 밀크 1+1 (트레이더스) | F4: ME00621H56
B5: 멘소래담 롤온 로션 50ml*2입 | C5: 8809020341733 | D5: ME80421DRT | E5: 멘소래담 마사지 롤온 로션 1+1 (트레이더스) | F5: ME80421DRT
B6: 하다라보 고쿠쥰 로션 170mL*2 | C6: 8809020341238 | D6: ME00621H55 | E6: 하다라보 고쿠쥰 로션 1+1(트레이더스) | F6: ME00621H55
B7: 아크네스 포맨 퍼펙트 올인원 | C7: 8809020341870 | D7: ME00621FAA | E7: 아크네스 포맨 스킨+올인원 세트 (트레이더스)
B8: 하다라보 고쿠쥰 로션 170ml*2입 | C8: 8809020342297 | D8: ME90621L2L | E8: 하다라보 고쿠쥰 로션 170ml*2입
B9: 하다라보 고쿠쥰 밀크 140ml*2입 | C9: 8809020342303 | D9: ME90621M2M | E9: 하다라보 고쿠쥰 밀크 140ml*2입
B10: 신)멘소래담 롤온 로션 50ml*2입 | C10: 8809020343195 | D10: ME80421DTD | E10: 신)멘소래담 롤온 로션 50ml*2입 | G10: 롤온핫 KR버전
B11: 멘소래담 스프레이 파스 쿨 180ml*3입 | C11: 8809020343515 | D11: ME00421189 | E11: 멘소래담 스프레이 파스 쿨 180ml*3입 | F11: ME00421189
B12: 아크네스 포맨 퍼펙트 올인원 200ml+30ml*2 | C12: 8809020343591 | D12: ME00621FAT | E12: 아크네스 포맨 퍼펙트 올인원 200ml+30ml x 2 (트레이더스) | F12: ME00621FAT
B13: 하다라보 고쿠쥰 밀크 140ml*2입 | C13: 8809020344901 | D13: ME90621M3M | E13: 하다라보 고쿠쥰 밀크 140ml*2입
B14: 하다라보 고쿠쥰 로션 170ml*2입 | C14: 8809020344895 | D14: ME90621L3L | E14: 하다라보 고쿠쥰 로션 170ml*2입
