Workbook

Sheet Raw data
A1: 발주일자 | B1: 업체코드 | C1: 업체명 | D1: 점포코드 | E1: 점포명 | F1: 상품코드 | G1: 상품명 | H1: 발주원가 | I1: 발주단위 | J1: LOT | K1: 수량 | L1: 발주금액 | M1: 전표번호 | N1: 바이어명 | O1: 센터입하일자 | P1: 센터코드 | Q1: 점입점일자 | R1: 납품구분 | S1: 기타(점코드) | T1: 기타(점포명)
A2: 20260415 | B2: 1368001 | C2: 맨소래덤아시아퍼시픽 주식회사 | D2: 1020 | E2: EM이천점 | F2: 8809020345212 | G2: 맨소래담 스프레이쿨180ml | H2: 2326 | I2: 8 | J2: 1 | K2: 8 | L2: 18608 | M2: 1283287135 | N2: 최철원 | O2: 20260417 | P2: 9120 | Q2: 여주DRY센터 | R2: 20260417 | S2: TC | T2: 1020 | U2: EM이천점 | AA2: 매장 창고
A3: 20260415 | B3: 1368001 | C3: 맨소래덤아시아퍼시픽 주식회사 | D3: 1035 | E3: EM포항점 | F3: 8809020345212 | G3: 맨소래담 스프레이쿨180ml | H3: 2326 | I3: 8 | J3: 1 | K3: 8 | L3: 18608 | M3: 1283293862 | N3: 최철원 | O3: 20260417 | P3: 9100 | Q3: 대구DRY센터 | R3: 20260417 | S3: TC | T3: 1035 | U3: EM포항점 | AA3: 매장 창고
A4: 20260415 | B4: 1368001 | C4: 맨소래덤아시아퍼시픽 주식회사 | D4: 1044 | E4: EM안산고잔점 | F4: 8809020346509 | G4: 아크네스 포밍워시 200ml | H4: 4469 | I4: 6 | J4: 1 | K4: 6 | L4: 26814 | M4: 1283298238 | N4: 최철원 | O4: 20260417 | P4: 9110 | Q4: 시화DRY센터 | R4: 20260417 | S4: TC | T4: 1044 | U4: EM안산고잔점 | AA4: 매장 창고
A5: 20260415 | B5: 1368001 | C5: 맨소래덤아시아퍼시픽 주식회사 | D5: 1044 | E5: EM안산고잔점 | F5: 8809020344321 | G5: 멜라노CC 엔자임 페이스 워시 130g | H5: 4284 | I5: 12 | J5: 1 | K5: 12 | L5: 51408 | M5: 1283298238 | N5: 최철원 | O5: 20260417 | P5: 9110 | Q5: 시화DRY센터 | R5: 20260417 | S5: TC | T5: 1044 | U5: EM안산고잔점 | AA5: 매장 창고
A6: 20260415 | B6: 1368001 | C6: 맨소래덤아시아퍼시픽 주식회사 | D6: 1046 | E6: EM금정점 | F6: 8809020344321 | G6: 멜라노CC 엔자임 페이스 워시 130g | H6: 4284 | I6: 12 | J6: 1 | K6: 12 | L6: 51408 | M6: 1283299700 | N6: 최철원 | O6: 20260417 | P6: 9100 | Q6: 대구DRY센터 | R6: 20260417 | S6: TC | T6: 1046 | U6: EM금정점 | AA6: 매장 창고
A7: 20260415 | B7: 1368001 | C7: 맨소래덤아시아퍼시픽 주식회사 | D7: 1056 | E7: EM양산점 | F7: 8809020345212 | G7: 맨소래담 스프레이쿨180ml | H7: 2326 | I7: 8 | J7: 1 | K7: 8 | L7: 18608 | M7: 1283304859 | N7: 최철원 | O7: 20260417 | P7: 9100 | Q7: 대구DRY센터 | R7: 20260417 | S7: TC | T7: 1056 | U7: EM양산점 | AA7: 매장 창고
A8: 20260415 | B8: 1368001 | C8: 맨소래덤아시아퍼시픽 주식회사 | D8: 1061 | E8: EM안동점 | F8: 8809020345212 | G8: 맨소래담 스프레이쿨180ml | H8: 2326 | I8: 8 | J8: 1 | K8: 8 | L8: 18608 | M8: 1283306926 | N8: 최철원 | O8: 20260417 | P8: 9120 | Q8: 여주DRY센터 | R8: 20260417 | S8: TC | T8: 1061 | U8: EM안동점 | AA8: 매장 창고
A9: 20260415 | B9: 1368001 | C9: 맨소래덤아시아퍼시픽 주식회사 | D9: 1066 | E9: EM춘천점 | F9: 8809020345212 | G9: 맨소래담 스프레이쿨180ml | H9: 2326 | I9: 8 | J9: 1 | K9: 8 | L9: 18608 | M9: 1283308885 | N9: 최철원 | O9: 20260417 | P9: 9120 | Q9: 여주DRY센터 | R9: 20260417 | S9: TC | T9: 1066 | U9: EM춘천점 | AA9: 매장 창고
A10: 20260415 | B10: 1368001 | C10: 맨소래덤아시아퍼시픽 주식회사 | D10: 1102 | E10: EM포항이동점 | F10: 8809020345212 | G10: 맨소래담 스프레이쿨180ml | H10: 2326 | I10: 8 | J10: 1 | K10: 8 | L10: 18608 | M10: 1283323916 | N10: 최철원 | O10: 20260417 | P10: 9100 | Q10: 대구DRY센터 | R10: 20260417 | S10: TC | T10: 1102 | U10: EM포항이동점 | AA10: 매장 창고
A11: 20260415 | B11: 1368001 | C11: 맨소래덤아시아퍼시픽 주식회사 | D11: 1106 | E11: EM영등포점 | F11: 8809020345212 | G11: 맨소래담 스프레이쿨180ml | H11: 2326 | I11: 8 | J11: 1 | K11: 8 | L11: 18608 | M11: 1283324954 | N11: 최철원 | O11: 20260417 | P11: 9110 | Q11: 시화DRY센터 | R11: 20260417 | S11: TC | T11: 1106 | U11: EM영등포점 | AA11: 매장 창고
A12: 20260415 | B12: 1368001 | C12: 맨소래덤아시아퍼시픽 주식회사 | D12: 1114 | E12: EM천안터미널점 | F12: 8809020345212 | G12: 맨소래담 스프레이쿨180ml | H12: 2326 | I12: 8 | J12: 1 | K12: 8 | L12: 18608 | M12: 1283328003 | N12: 최철원 | O12: 20260417 | P12: 9120 | Q12: 여주DRY센터 | R12: 20260417 | S12: TC | T12: 1114 | U12: EM천안터미널점 | AA12: 매장 창고
A13: 20260415 | B13: 1368001 | C13: 맨소래덤아시아퍼시픽 주식회사 | D13: 1119 | E13: EM파주운정점 | F13: 8809020346509 | G13: 아크네스 포밍워시 200ml | H13: 4469 | I13: 6 | J13: 1 | K13: 6 | L13: 26814 | M13: 1283329600 | N13: 최철원 | O13: 20260417 | P13: 9110 | Q13: 시화DRY센터 | R13: 20260417 | S13: TC | T13: 1119 | U13: EM파주운정점 | AA13: 매장 창고
... A15: 20260415 | B15: 1368001 | C15: 맨소래덤아시아퍼시픽 주식회사 | D15: 1142 | E15: EMF고덕점 | F15: 8809020344321 | G15: 멜라노CC 엔자임 페이스 워시 130g | H15: 4284 | I15: 12 | J15: 1 | K15: 12 | L15: 51408 | M15: 1283337768 | N15: 최철원 | O15: 20260417 | P15: 9120 | Q15: 여주DRY센터 | R15: 20260417 | S15: TC | T15: 1142 | U15: EMF고덕점 | AA15: 매장 창고
A16: 20260415 | B16: 1368001 | C16: 맨소래덤아시아퍼시픽 주식회사 | D16: 9120 | E16: 여주DRY센터 | F16: 8809020344321 | G16: 멜라노CC 엔자임 페이스 워시 130g | H16: 4284 | I16: 12 | J16: 1 | K16: 12 | L16: 51408 | M16: 1283416884 | N16: 최철원 | O16: 20260417 | P16: 9120 | Q16: 여주DRY센터 | R16: 20260417 | S16: TDC | T16: 9120 | U16: 여주DRY센터 | V16: 85 | W16: 귀착지 : EM보정몰가상점 | Y16: 8503 | AA16: 매장 창고
A17: 20260415 | B17: 1368001 | C17: 맨소래덤아시아퍼시픽 주식회사 | D17: 1025 | E17: EM군산점 | F17: 8809020346592 | G17: 아크네스 데일리 딥클렌저 100g | H17: 3656 | I17: 6 | J17: 1 | K17: 6 | L17: 21936 | M17: 1283491582 | N17: 최철원 | O17: 20260417 | P17: 9120 | Q17: 여주DRY센터 | R17: 20260417 | S17: TC | T17: 1025 | U17: EM군산점 | AA17: 매장 창고
A18: 20260415 | B18: 1368001 | C18: 맨소래덤아시아퍼시픽 주식회사 | D18: 1025 | E18: EM군산점 | F18: 8809020346509 | G18: 아크네스 포밍워시 200ml | H18: 4469 | I18: 6 | J18: 1 | K18: 6 | L18: 26814 | M18: 1283491582 | N18: 최철원 | O18: 20260417 | P18: 9120 | Q18: 여주DRY센터 | R18: 20260417 | S18: TC | T18: 1025 | U18: EM군산점 | AA18: 매장 창고
A19: 20260415 | B19: 1368001 | C19: 맨소래덤아시아퍼시픽 주식회사 | D19: 1083 | E19: EM신도림점 | F19: 8809020346509 | G19: 아크네스 포밍워시 200ml | H19: 4469 | I19: 6 | J19: 1 | K19: 6 | L19: 26814 | M19: 1283491676 | N19: 최철원 | O19: 20260417 | P19: 9110 | Q19: 시화DRY센터 | R19: 20260417 | S19: TC | T19: 1083 | U19: EM신도림점 | AA19: 매장 창고
A20: 20260415 | B20: 1368001 | C20: 맨소래덤아시아퍼시픽 주식회사 | D20: 1036 | E20: EM연제점 | F20: 8809020346509 | G20: 아크네스 포밍워시 200ml | H20: 4469 | I20: 6 | J20: 1 | K20: 6 | L20: 26814 | M20: 1283491677 | N20: 최철원 | O20: 20260417 | P20: 9100 | Q20: 대구DRY센터 | R20: 20260417 | S20: TC | T20: 1036 | U20: EM연제점 | AA20: 매장 창고
A21: 20260415 | B21: 1368001 | C21: 맨소래덤아시아퍼시픽 주식회사 | D21: 1112 | E21: EM광명소하점 | F21: 8809020346585 | G21: 아크네스 클리어앤화이트 포밍워시 150g | H21: 4469 | I21: 6 | J21: 1 | K21: 6 | L21: 26814 | M21: 1283492010 | N21: 최철원 | O21: 20260417 | P21: 9110 | Q21: 시화DRY센터 | R21: 20260417 | S21: TC | T21: 1112 | U21: EM광명소하점 | AA21: 매장 창고
A22: 20260415 | B22: 1368001 | C22: 맨소래덤아시아퍼시픽 주식회사 | D22: 1015 | E22: EM산본점 | F22: 8809020345212 | G22: 맨소래담 스프레이쿨180ml | H22: 2326 | I22: 8 | J22: 1 | K22: 8 | L22: 18608 | M22: 1283505625 | N22: 최철원 | O22: 20260417 | P22: 9110 | Q22: 시화DRY센터 | R22: 20260417 | S22: TC | T22: 1015 | U22: EM산본점 | AA22: 매장 창고
A23: 20260415 | B23: 1368001 | C23: 맨소래덤아시아퍼시픽 주식회사 | D23: 1018 | E23: EM해운대점 | F23: 8809020346585 | G23: 아크네스 클리어앤화이트 포밍워시 150g | H23: 4469 | I23: 6 | J23: 1 | K23: 6 | L23: 26814 | M23: 1283505750 | N23: 최철원 | O23: 20260417 | P23: 9100 | Q23: 대구DRY센터 | R23: 20260417 | S23: TC | T23: 1018 | U23: EM해운대점 | AA23: 매장 창고
A24: 20260415 | B24: 1368001 | C24: 맨소래덤아시아퍼시픽 주식회사 | D24: 1061 | E24: EM안동점 | F24: 8809020346592 | G24: 아크네스 데일리 딥클렌저 100g | H24: 3656 | I24: 6 | J24: 1 | K24: 6 | L24: 21936 | M24: 1283509767 | N24: 최철원 | O24: 20260417 | P24: 9120 | Q24: 여주DRY센터 | R24: 20260417 | S24: TC | T24: 1061 | U24: EM안동점 | AA24: 매장 창고
A25: 20260415 | B25: 1368001 | C25: 맨소래덤아시아퍼시픽 주식회사 | D25: 1061 | E25: EM안동점 | F25: 8809020349166 | G25: 고쿠쥰오일클렌징200ml | H25: 5271 | I25: 12 | J25: 1 | K25: 12 | L25: 63252 | M25: 1283509767 | N25: 최철원 | O25: 20260417 | P25: 9120 | Q25: 여주DRY센터 | R25: 20260417 | S25: TC | T25: 1061 | U25: EM안동점 | AA25: 매장 창고

Sheet SUM(히아풀젤,폼 아이캐쳐붙인걸로)
A2: 데일리 딥 , 화이트 포밍 1+1
A3: 합계 : 수량
A4: MECODE | B4: 상품명 | C4: 발주원가 | D4: 요약 | F4: 재고 | G4: 잔여재고 | I4: 히아풀 수딩 젤&수딩 폼
A5: ME00621AN5 | B5: 아크네스 세범 밸런싱 스킨 2.0 | C5: 3875 | D5: 84 | I5: 무조건 E로 붙여진거 출고할것 !!!!
A6: ME00621ASM | B6: 아크네스 스팟클리어크림패치 18g | C6: 3861 | D6: 54
A7: ME00621AN4 | B7: 아크네스 모이스처크림2.0 60ml | C7: 4650 | D7: 48
A8: ME90621AC4 | B8: 아크네스 클리어 화이트 크리미워시 100g | C8: 3488 | D8: 48 | E8: 9B4
A9: ME00621AN6 | B9: 아크네스 모이스처 플루이드 150ml | C9: 3875 | D9: 84 | E9: ME90621A05
A10: ME00621HPC | B10: 하다라보 히아풀베리어 포어 클렌징폼 150g | C10: 3868 | D10: 12
A11: ME90621NA7 | B11: 아크네스 클리어앤화이트 포밍워시 150g | C11: 7750 | D11: 12
A12: ME90621ADI | B12: 아크네스 데일리 딥클렌저 100g | C12: 6975 | D12: 36
A13: ME90621GO8 | B13: 고쿠쥰오일클렌징200ml | C13: 5028 | D13: 48
A14: ME90521EL7 | B14: 립아이스 매직칼라 틴티드 컬러 레드 2g | C14: 2790 | D14: 504
A15: ME90521EL9 | B15: 딥모이스트 멘톨 4.5g | C15: 3513 | D15: 650
A16: ME90521E18 | B16: 메디케이티드립젤트윈팩3.5g*2 | C16: 2428 | D16: 420
A17: ME90521EL6 | B17: 립아이스 매직칼라 딸기향 2g | C17: 2790 | D17: 444
A18: ME90521EL4 | B18: 메디케이티드립밤3.5g | C18: 1963 | D18: 960
A19: ME90521GS2 | B19: 립아이스 립밤 스트로베리 | C19: 2169 | D19: 492
A20: ME90521GT2 | B20: 립아이스 립밤 그레이프프루트 티 | C20: 2169 | D20: 480
A21: ME90521EL8 | B21: 딥모이스트 네츄럴 4.5g | C21: 3513 | D21: 400
... A23: ME00621CM5 | B23: 고쿠쥰훼이스워시100g | C23: 7220 | D23: 12
A24: ME80421DR2 | B24: 멘소래담 마사지 롤온 로션 50ml | C24: 5115 | D24: 5 | E24: 입수전환
A25: 총합계 | D25: 4985

Sheet 서식(직납)
A1: 발주일자 | B1: Sumcode | C1: 점포명 | D1: 점포코드 | E1: 센터코드 | F1: 배송코드 | G1: 바코드 | H1: 상품명 | I1: MECODE | J1: 수량 | K1: 발주원가 | L1: 발주금액 | M1: 전표번호 | N1: 바이어명 | O1: 센터입하일자 | P1: 센터코드 | Q1: 점입점일자 | R1: 납품구분 | S1: 기타(점코드) | T1: 기타(점포명)
B2: =F2&I2 -> #REF! | C2: ='Raw data'!#REF! -> #REF! | D2: =VLOOKUP(C2,'점포코드 '!A:B,2,0) -> #REF! | E2: ='Raw data'!#REF! -> #REF! | F2: =VLOOKUP(E2,'점포코드 '!$A$2:$C$247,2,0) -> #REF! | G2: ='Raw data'!#REF! -> #REF! | H2: ='Raw data'!#REF! -> #REF! | I2: =VLOOKUP(G2,제품명!$C$1:$E$114,2,0) -> #REF! | J2: ='Raw data'!#REF! -> #REF! | K2: ='Raw data'!#REF! -> #REF! | L2: =J2*K2 -> #REF!
B3: =F3&I3 -> #REF! | C3: ='Raw data'!#REF! -> #REF! | D3: =VLOOKUP(C3,'점포코드 '!A:B,2,0) -> #REF! | E3: ='Raw data'!#REF! -> #REF! | F3: =VLOOKUP(E3,'점포코드 '!$A$2:$C$247,2,0) -> #REF! | G3: ='Raw data'!#REF! -> #REF! | H3: ='Raw data'!#REF! -> #REF! | I3: =VLOOKUP(G3,제품명!$C$1:$E$114,2,0) -> #REF! | J3: ='Raw data'!#REF! -> #REF! | K3: ='Raw data'!#REF! -> #REF! | L3: =J3*K3 -> #REF!
B4: =F4&I4 -> #REF! | C4: ='Raw data'!#REF! -> #REF! | D4: =VLOOKUP(C4,'점포코드 '!A:B,2,0) -> #REF! | E4: ='Raw data'!#REF! -> #REF! | F4: =VLOOKUP(E4,'점포코드 '!$A$2:$C$247,2,0) -> #REF! | G4: ='Raw data'!#REF! -> #REF! | H4: ='Raw data'!#REF! -> #REF! | I4: =VLOOKUP(G4,제품명!$C$1:$E$114,2,0) -> #REF! | J4: ='Raw data'!#REF! -> #REF! | K4: ='Raw data'!#REF! -> #REF! | L4: =J4*K4 -> #REF!
B5: =F5&I5 -> #REF! | C5: ='Raw data'!#REF! -> #REF! | D5: =VLOOKUP(C5,'점포코드 '!A:B,2,0) -> #REF! | E5: ='Raw data'!#REF! -> #REF! | F5: =VLOOKUP(E5,'점포코드 '!$A$2:$C$247,2,0) -> #REF! | G5: ='Raw data'!#REF! -> #REF! | H5: ='Raw data'!#REF! -> #REF! | I5: =VLOOKUP(G5,제품명!$C$1:$E$114,2,0) -> #REF! | J5: ='Raw data'!#REF! -> #REF! | K5: ='Raw data'!#REF! -> #REF! | L5: =J5*K5 -> #REF!
B6: =F6&I6 -> #REF! | C6: ='Raw data'!#REF! -> #REF! | D6: =VLOOKUP(C6,'점포코드 '!A:B,2,0) -> #REF! | E6: ='Raw data'!#REF! -> #REF! | F6: =VLOOKUP(E6,'점포코드 '!$A$2:$C$247,2,0) -> #REF! | G6: ='Raw data'!#REF! -> #REF! | H6: ='Raw data'!#REF! -> #REF! | I6: =VLOOKUP(G6,제품명!$C$1:$E$114,2,0) -> #REF! | J6: ='Raw data'!#REF! -> #REF! | K6: ='Raw data'!#REF! -> #REF! | L6: =J6*K6 -> #REF!
B7: =F7&I7 -> #REF! | C7: ='Raw data'!#REF! -> #REF! | D7: =VLOOKUP(C7,'점포코드 '!A:B,2,0) -> #REF! | E7: ='Raw data'!#REF! -> #REF! | F7: =VLOOKUP(E7,'점포코드 '!$A$2:$C$247,2,0) -> #REF! | G7: ='Raw data'!#REF! -> #REF! | H7: ='Raw data'!#REF! -> #REF! | I7: =VLOOKUP(G7,제품명!$C$1:$E$114,2,0) -> #REF! | J7: ='Raw data'!#REF! -> #REF! | K7: ='Raw data'!#REF! -> #REF! | L7: =J7*K7 -> #REF!
B8: =F8&I8 -> #REF! | C8: ='Raw data'!#REF! -> #REF! | D8: =VLOOKUP(C8,'점포코드 '!A:B,2,0) -> #REF! | E8: ='Raw data'!#REF! -> #REF! | F8: =VLOOKUP(E8,'점포코드 '!$A$2:$C$247,2,0) -> #REF! | G8: ='Raw data'!#REF! -> #REF! | H8: ='Raw data'!#REF! -> #REF! | I8: =VLOOKUP(G8,제품명!$C$1:$E$114,2,0) -> #REF! | J8: ='Raw data'!#REF! -> #REF! | K8: ='Raw data'!#REF! -> #REF! | L8: =J8*K8 -> #REF!
B9: =F9&I9 -> #REF! | C9: ='Raw data'!#REF! -> #REF! | D9: =VLOOKUP(C9,'점포코드 '!A:B,2,0) -> #REF! | E9: ='Raw data'!#REF! -> #REF! | F9: =VLOOKUP(E9,'점포코드 '!$A$2:$C$247,2,0) -> #REF! | G9: ='Raw data'!#REF! -> #REF! | H9: ='Raw data'!#REF! -> #REF! | I9: =VLOOKUP(G9,제품명!$C$1:$E$114,2,0) -> #REF! | J9: ='Raw data'!#REF! -> #REF! | K9: ='Raw data'!#REF! -> #REF! | L9: =J9*K9 -> #REF!
B10: =F10&I10 -> #REF! | C10: ='Raw data'!#REF! -> #REF! | D10: =VLOOKUP(C10,'점포코드 '!A:B,2,0) -> #REF! | E10: ='Raw data'!#REF! -> #REF! | F10: =VLOOKUP(E10,'점포코드 '!$A$2:$C$247,2,0) -> #REF! | G10: ='Raw data'!#REF! -> #REF! | H10: ='Raw data'!#REF! -> #REF! | I10: =VLOOKUP(G10,제품명!$C$1:$E$114,2,0) -> #REF! | J10: ='Raw data'!#REF! -> #REF! | K10: ='Raw data'!#REF! -> #REF! | L10: =J10*K10 -> #REF!
B11: =F11&I11 -> #REF! | C11: ='Raw data'!#REF! -> #REF! | D11: =VLOOKUP(C11,'점포코드 '!A:B,2,0) -> #REF! | E11: ='Raw data'!#REF! -> #REF! | F11: =VLOOKUP(E11,'점포코드 '!$A$2:$C$247,2,0) -> #REF! | G11: ='Raw data'!#REF! -> #REF! | H11: ='Raw data'!#REF! -> #REF! | I11: =VLOOKUP(G11,제품명!$C$1:$E$114,2,0) -> #REF! | J11: ='Raw data'!#REF! -> #REF! | K11: ='Raw data'!#REF! -> #REF! | L11: =J11*K11 -> #REF!
B12: =F12&I12 -> #REF! | C12: ='Raw data'!#REF! -> #REF! | D12: =VLOOKUP(C12,'점포코드 '!A:B,2,0) -> #REF! | E12: ='Raw data'!#REF! -> #REF! | F12: =VLOOKUP(E12,'점포코드 '!$A$2:$C$247,2,0) -> #REF! | G12: ='Raw data'!#REF! -> #REF! | H12: ='Raw data'!#REF! -> #REF! | I12: =VLOOKUP(G12,제품명!$C$1:$E$114,2,0) -> #REF! | J12: ='Raw data'!#REF! -> #REF! | K12: ='Raw data'!#REF! -> #REF! | L12: =J12*K12 -> #REF!
B13: =F13&I13 -> #REF! | C13: ='Raw data'!#REF! -> #REF! | D13: =VLOOKUP(C13,'점포코드 '!A:B,2,0) -> #REF! | E13: ='Raw data'!#REF! -> #REF! | F13: =VLOOKUP(E13,'점포코드 '!$A$2:$C$247,2,0) -> #REF! | G13: ='Raw data'!#REF! -> #REF! | H13: ='Raw data'!#REF! -> #REF! | I13: =VLOOKUP(G13,제품명!$C$1:$E$114,2,0) -> #REF! | J13: ='Raw data'!#REF! -> #REF! | K13: ='Raw data'!#REF! -> #REF! | L13: =J13*K13 -> #REF!
... B37: =F37&I37 -> #REF! | C37: ='Raw data'!#REF! -> #REF! | D37: =VLOOKUP(C37,'점포코드 '!A:B,2,0) -> #REF! | E37: ='Raw data'!#REF! -> #REF! | F37: =VLOOKUP(E37,'점포코드 '!$A$2:$C$247,2,0) -> #REF! | G37: ='Raw data'!#REF! -> #REF! | H37: ='Raw data'!#REF! -> #REF! | I37: =VLOOKUP(G37,제품명!$C$1:$E$114,2,0) -> #REF! | J37: ='Raw data'!#REF! -> #REF! | K37: ='Raw data'!#REF! -> #REF! | L37: =J37*K37 -> #REF!
B38: =F38&I38 -> #REF! | C38: ='Raw data'!#REF! -> #REF! | D38: =VLOOKUP(C38,'점포코드 '!A:B,2,0) -> #REF! | E38: ='Raw data'!#REF! -> #REF! | F38: =VLOOKUP(E38,'점포코드 '!A:B,2,0) -> #REF! | G38: ='Raw data'!#REF! -> #REF! | H38: ='Raw data'!#REF! -> #REF! | I38: =VLOOKUP(G38,제품명!$C$1:$E$114,2,0) -> #REF! | J38: ='Raw data'!#REF! -> #REF! | K38: ='Raw data'!#REF! -> #REF! | L38: =J38*K38 -> #REF!
B39: =F39&I39 -> #REF! | C39: ='Raw data'!#REF! -> #REF! | D39: =VLOOKUP(C39,'점포코드 '!A:B,2,0) -> #REF! | E39: ='Raw data'!#REF! -> #REF! | F39: =VLOOKUP(E39,'점포코드 '!A:B,2,0) -> #REF! | G39: ='Raw data'!#REF! -> #REF! | H39: ='Raw data'!#REF! -> #REF! | I39: =VLOOKUP(G39,제품명!$C$1:$E$114,2,0) -> #REF! | J39: ='Raw data'!#REF! -> #REF! | K39: ='Raw data'!#REF! -> #REF! | L39: =J39*K39 -> #REF!
B40: =F40&I40 -> #REF! | C40: ='Raw data'!#REF! -> #REF! | D40: =VLOOKUP(C40,'점포코드 '!A:B,2,0) -> #REF! | E40: ='Raw data'!#REF! -> #REF! | F40: =VLOOKUP(E40,'점포코드 '!A:B,2,0) -> #REF! | G40: ='Raw data'!#REF! -> #REF! | H40: ='Raw data'!#REF! -> #REF! | I40: =VLOOKUP(G40,제품명!$C$1:$E$114,2,0) -> #REF! | J40: ='Raw data'!#REF! -> #REF! | K40: ='Raw data'!#REF! -> #REF! | L40: =J40*K40 -> #REF!
B41: =F41&I41 -> #REF! | C41: ='Raw data'!#REF! -> #REF! | D41: =VLOOKUP(C41,'점포코드 '!A:B,2,0) -> #REF! | E41: ='Raw data'!#REF! -> #REF! | F41: =VLOOKUP(E41,'점포코드 '!A:B,2,0) -> #REF! | G41: ='Raw data'!#REF! -> #REF! | H41: ='Raw data'!#REF! -> #REF! | I41: =VLOOKUP(G41,제품명!$C$1:$E$114,2,0) -> #REF! | J41: ='Raw data'!#REF! -> #REF! | K41: ='Raw data'!#REF! -> #REF! | L41: =J41*K41 -> #REF!
B42: =F42&I42 -> #REF! | C42: ='Raw data'!#REF! -> #REF! | D42: =VLOOKUP(C42,'점포코드 '!A:B,2,0) -> #REF! | E42: ='Raw data'!#REF! -> #REF! | F42: =VLOOKUP(E42,'점포코드 '!A:B,2,0) -> #REF! | G42: ='Raw data'!#REF! -> #REF! | H42: ='Raw data'!#REF! -> #REF! | I42: =VLOOKUP(G42,제품명!$C$1:$E$114,2,0) -> #REF! | J42: ='Raw data'!#REF! -> #REF! | K42: ='Raw data'!#REF! -> #REF! | L42: =J42*K42 -> #REF!
B43: =F43&I43 -> #REF! | C43: ='Raw data'!#REF! -> #REF! | D43: =VLOOKUP(C43,'점포코드 '!A:B,2,0) -> #REF! | E43: ='Raw data'!#REF! -> #REF! | F43: =VLOOKUP(E43,'점포코드 '!A:B,2,0) -> #REF! | G43: ='Raw data'!#REF! -> #REF! | H43: ='Raw data'!#REF! -> #REF! | I43: =VLOOKUP(G43,제품명!$C$1:$E$114,2,0) -> #REF! | J43: ='Raw data'!#REF! -> #REF! | K43: ='Raw data'!#REF! -> #REF! | L43: =J43*K43 -> #REF!
B44: =F44&I44 -> #REF! | C44: ='Raw data'!#REF! -> #REF! | D44: =VLOOKUP(C44,'점포코드 '!A:B,2,0) -> #REF! | E44: ='Raw data'!#REF! -> #REF! | F44: =VLOOKUP(E44,'점포코드 '!A:B,2,0) -> #REF! | G44: ='Raw data'!#REF! -> #REF! | H44: ='Raw data'!#REF! -> #REF! | I44: =VLOOKUP(G44,제품명!$C$1:$E$114,2,0) -> #REF! | J44: ='Raw data'!#REF! -> #REF! | K44: ='Raw data'!#REF! -> #REF! | L44: =J44*K44 -> #REF!
B45: =F45&I45 -> #REF! | C45: ='Raw data'!#REF! -> #REF! | D45: =VLOOKUP(C45,'점포코드 '!A:B,2,0) -> #REF! | E45: ='Raw data'!#REF! -> #REF! | F45: =VLOOKUP(E45,'점포코드 '!A:B,2,0) -> #REF! | G45: ='Raw data'!#REF! -> #REF! | H45: ='Raw data'!#REF! -> #REF! | I45: =VLOOKUP(G45,제품명!$C$1:$E$114,2,0) -> #REF! | J45: ='Raw data'!#REF! -> #REF! | K45: ='Raw data'!#REF! -> #REF! | L45: =J45*K45 -> #REF!
B46: =F46&I46 -> #REF! | C46: ='Raw data'!#REF! -> #REF! | D46: =VLOOKUP(C46,'점포코드 '!A:B,2,0) -> #REF! | E46: ='Raw data'!#REF! -> #REF! | F46: =VLOOKUP(E46,'점포코드 '!A:B,2,0) -> #REF! | G46: ='Raw data'!#REF! -> #REF! | H46: ='Raw data'!#REF! -> #REF! | I46: =VLOOKUP(G46,제품명!$C$1:$E$114,2,0) -> #REF! | J46: ='Raw data'!#REF! -> #REF! | K46: ='Raw data'!#REF! -> #REF! | L46: =J46*K46 -> #REF!
B47: =F47&I47 -> #REF! | C47: ='Raw data'!#REF! -> #REF! | D47: =VLOOKUP(C47,'점포코드 '!A:B,2,0) -> #REF! | E47: ='Raw data'!#REF! -> #REF! | F47: =VLOOKUP(E47,'점포코드 '!A:B,2,0) -> #REF! | G47: ='Raw data'!#REF! -> #REF! | H47: ='Raw data'!#REF! -> #REF! | I47: =VLOOKUP(G47,제품명!$C$1:$E$114,2,0) -> #REF! | J47: ='Raw data'!#REF! -> #REF! | K47: ='Raw data'!#REF! -> #REF! | L47: =J47*K47 -> #REF!
B48: =F48&I48 -> #REF! | C48: ='Raw data'!#REF! -> #REF! | D48: =VLOOKUP(C48,'점포코드 '!A:B,2,0) -> #REF! | E48: ='Raw data'!#REF! -> #REF! | F48: =VLOOKUP(E48,'점포코드 '!A:B,2,0) -> #REF! | G48: ='Raw data'!#REF! -> #REF! | H48: ='Raw data'!#REF! -> #REF! | I48: =VLOOKUP(G48,제품명!$C$1:$E$114,2,0) -> #REF! | J48: ='Raw data'!#REF! -> #REF! | K48: ='Raw data'!#REF! -> #REF! | L48: =J48*K48 -> #REF!
B49: =F49&I49 -> #REF! | C49: ='Raw data'!#REF! -> #REF! | D49: =VLOOKUP(C49,'점포코드 '!A:B,2,0) -> #REF! | E49: ='Raw data'!#REF! -> #REF! | F49: =VLOOKUP(E49,'점포코드 '!A:B,2,0) -> #REF! | G49: ='Raw data'!#REF! -> #REF! | H49: ='Raw data'!#REF! -> #REF! | I49: =VLOOKUP(G49,제품명!$C$1:$E$114,2,0) -> #REF! | J49: ='Raw data'!#REF! -> #REF! | K49: ='Raw data'!#REF! -> #REF! | L49: =J49*K49 -> #REF!
... B81: =F81&I81 -> #REF! | C81: ='Raw data'!#REF! -> #REF! | D81: =VLOOKUP(C81,'점포코드 '!A:B,2,0) -> #REF! | E81: ='Raw data'!#REF! -> #REF! | F81: =VLOOKUP(E81,'점포코드 '!A:B,2,0) -> #REF! | G81: ='Raw data'!#REF! -> #REF! | H81: ='Raw data'!#REF! -> #REF! | I81: =VLOOKUP(G81,제품명!$C$1:$E$114,2,0) -> #REF! | J81: ='Raw data'!#REF! -> #REF! | K81: ='Raw data'!#REF! -> #REF! | L81: =J81*K81 -> #REF!
B82: =F82&I82 -> 81010905ME00421186 | C82: ='Raw data'!E2 -> EM이천점 | D82: =VLOOKUP(C82,'점포코드 '!A:B,2,0) -> 1020 | E82: ='Raw data'!P2 -> 9120 | F82: =VLOOKUP(E82,'점포코드 '!A:B,2,0) -> 81010905 | G82: ='Raw data'!F2 -> 8809020345212 | H82: ='Raw data'!G2 -> 맨소래담 스프레이쿨180ml | I82: =VLOOKUP(G82,제품명!$C$1:$E$114,2,0) -> ME00421186 | J82: ='Raw data'!K2 -> 8 | K82: ='Raw data'!H2 -> 2326 | L82: =J82*K82 -> 18608
B83: =F83&I83 -> 81010903ME00421186 | C83: ='Raw data'!E3 -> EM포항점 | D83: =VLOOKUP(C83,'점포코드 '!A:B,2,0) -> 1035 | E83: ='Raw data'!P3 -> 9100 | F83: =VLOOKUP(E83,'점포코드 '!A:B,2,0) -> 81010903 | G83: ='Raw data'!F3 -> 8809020345212 | H83: ='Raw data'!G3 -> 맨소래담 스프레이쿨180ml | I83: =VLOOKUP(G83,제품명!$C$1:$E$114,2,0) -> ME00421186 | J83: ='Raw data'!K3 -> 8 | K83: ='Raw data'!H3 -> 2326 | L83: =J83*K83 -> 18608
B84: =F84&I84 -> 81010902ME90621AFE | C84: ='Raw data'!E4 -> EM안산고잔점 | D84: =VLOOKUP(C84,'점포코드 '!A:B,2,0) -> 1044 | E84: ='Raw data'!P4 -> 9110 | F84: =VLOOKUP(E84,'점포코드 '!A:B,2,0) -> 81010902 | G84: ='Raw data'!F4 -> 8809020346509 | H84: ='Raw data'!G4 -> 아크네스 포밍워시 200ml | I84: =VLOOKUP(G84,제품명!$C$1:$E$114,2,0) -> ME90621AFE | J84: ='Raw data'!K4 -> 6 | K84: ='Raw data'!H4 -> 4469 | L84: =J84*K84 -> 26814
B85: =F85&I85 -> 81010902ME90621MAM | C85: ='Raw data'!E5 -> EM안산고잔점 | D85: =VLOOKUP(C85,'점포코드 '!A:B,2,0) -> 1044 | E85: ='Raw data'!P5 -> 9110 | F85: =VLOOKUP(E85,'점포코드 '!A:B,2,0) -> 81010902 | G85: ='Raw data'!F5 -> 8809020344321 | H85: ='Raw data'!G5 -> 멜라노CC 엔자임 페이스 워시 130g | I85: =VLOOKUP(G85,제품명!$C$1:$E$114,2,0) -> ME90621MAM | J85: ='Raw data'!K5 -> 12 | K85: ='Raw data'!H5 -> 4284 | L85: =J85*K85 -> 51408
B86: =F86&I86 -> 81010903ME90621MAM | C86: ='Raw data'!E6 -> EM금정점 | D86: =VLOOKUP(C86,'점포코드 '!A:B,2,0) -> #N/A | E86: ='Raw data'!P6 -> 9100 | F86: =VLOOKUP(E86,'점포코드 '!A:B,2,0) -> 81010903 | G86: ='Raw data'!F6 -> 8809020344321 | H86: ='Raw data'!G6 -> 멜라노CC 엔자임 페이스 워시 130g | I86: =VLOOKUP(G86,제품명!$C$1:$E$114,2,0) -> ME90621MAM | J86: ='Raw data'!K6 -> 12 | K86: ='Raw data'!H6 -> 4284 | L86: =J86*K86 -> 51408
B87: =F87&I87 -> 81010903ME00421186 | C87: ='Raw data'!E7 -> EM양산점 | D87: =VLOOKUP(C87,'점포코드 '!A:B,2,0) -> #N/A | E87: ='Raw data'!P7 -> 9100 | F87: =VLOOKUP(E87,'점포코드 '!A:B,2,0) -> 81010903 | G87: ='Raw data'!F7 -> 8809020345212 | H87: ='Raw data'!G7 -> 맨소래담 스프레이쿨180ml | I87: =VLOOKUP(G87,제품명!$C$1:$E$114,2,0) -> ME00421186 | J87: ='Raw data'!K7 -> 8 | K87: ='Raw data'!H7 -> 2326 | L87: =J87*K87 -> 18608
B88: =F88&I88 -> 81010905ME00421186 | C88: ='Raw data'!E8 -> EM안동점 | D88: =VLOOKUP(C88,'점포코드 '!A:B,2,0) -> 1061 | E88: ='Raw data'!P8 -> 9120 | F88: =VLOOKUP(E88,'점포코드 '!A:B,2,0) -> 81010905 | G88: ='Raw data'!F8 -> 8809020345212 | H88: ='Raw data'!G8 -> 맨소래담 스프레이쿨180ml | I88: =VLOOKUP(G88,제품명!$C$1:$E$114,2,0) -> ME00421186 | J88: ='Raw data'!K8 -> 8 | K88: ='Raw data'!H8 -> 2326 | L88: =J88*K88 -> 18608
B89: =F89&I89 -> 81010905ME00421186 | C89: ='Raw data'!E9 -> EM춘천점 | D89: =VLOOKUP(C89,'점포코드 '!A:B,2,0) -> 1066 | E89: ='Raw data'!P9 -> 9120 | F89: =VLOOKUP(E89,'점포코드 '!A:B,2,0) -> 81010905 | G89: ='Raw data'!F9 -> 8809020345212 | H89: ='Raw data'!G9 -> 맨소래담 스프레이쿨180ml | I89: =VLOOKUP(G89,제품명!$C$1:$E$114,2,0) -> ME00421186 | J89: ='Raw data'!K9 -> 8 | K89: ='Raw data'!H9 -> 2326 | L89: =J89*K89 -> 18608
B90: =F90&I90 -> 81010903ME00421186 | C90: ='Raw data'!E10 -> EM포항이동점 | D90: =VLOOKUP(C90,'점포코드 '!A:B,2,0) -> 1102 | E90: ='Raw data'!P10 -> 9100 | F90: =VLOOKUP(E90,'점포코드 '!A:B,2,0) -> 81010903 | G90: ='Raw data'!F10 -> 8809020345212 | H90: ='Raw data'!G10 -> 맨소래담 스프레이쿨180ml | I90: =VLOOKUP(G90,제품명!$C$1:$E$114,2,0) -> ME00421186 | J90: ='Raw data'!K10 -> 8 | K90: ='Raw data'!H10 -> 2326 | L90: =J90*K90 -> 18608
B91: =F91&I91 -> 81010902ME00421186 | C91: ='Raw data'!E11 -> EM영등포점 | D91: =VLOOKUP(C91,'점포코드 '!A:B,2,0) -> #N/A | E91: ='Raw data'!P11 -> 9110 | F91: =VLOOKUP(E91,'점포코드 '!A:B,2,0) -> 81010902 | G91: ='Raw data'!F11 -> 8809020345212 | H91: ='Raw data'!G11 -> 맨소래담 스프레이쿨180ml | I91: =VLOOKUP(G91,제품명!$C$1:$E$114,2,0) -> ME00421186 | J91: ='Raw data'!K11 -> 8 | K91: ='Raw data'!H11 -> 2326 | L91: =J91*K91 -> 18608
B92: =F92&I92 -> 81010905ME00421186 | C92: ='Raw data'!E12 -> EM천안터미널점 | D92: =VLOOKUP(C92,'점포코드 '!A:B,2,0) -> #N/A | E92: ='Raw data'!P12 -> 9120 | F92: =VLOOKUP(E92,'점포코드 '!A:B,2,0) -> 81010905 | G92: ='Raw data'!F12 -> 8809020345212 | H92: ='Raw data'!G12 -> 맨소래담 스프레이쿨180ml | I92: =VLOOKUP(G92,제품명!$C$1:$E$114,2,0) -> ME00421186 | J92: ='Raw data'!K12 -> 8 | K92: ='Raw data'!H12 -> 2326 | L92: =J92*K92 -> 18608
B93: =F93&I93 -> 81010902ME90621AFE | C93: ='Raw data'!E13 -> EM파주운정점 | D93: =VLOOKUP(C93,'점포코드 '!A:B,2,0) -> #N/A | E93: ='Raw data'!P13 -> 9110 | F93: =VLOOKUP(E93,'점포코드 '!A:B,2,0) -> 81010902 | G93: ='Raw data'!F13 -> 8809020346509 | H93: ='Raw data'!G13 -> 아크네스 포밍워시 200ml | I93: =VLOOKUP(G93,제품명!$C$1:$E$114,2,0) -> ME90621AFE | J93: ='Raw data'!K13 -> 6 | K93: ='Raw data'!H13 -> 4469 | L93: =J93*K93 -> 26814
... B267: =F267&I267 -> #N/A | C267: ='Raw data'!E187 -> 0 | D267: =VLOOKUP(C267,'점포코드 '!A:B,2,0) -> #N/A | E267: ='Raw data'!P187 -> 0 | F267: =VLOOKUP(E267,'점포코드 '!A:B,2,0) -> #N/A | G267: ='Raw data'!F187 -> 0 | H267: ='Raw data'!G187 -> 0 | I267: =VLOOKUP(G267,제품명!$C$1:$E$114,2,0) -> #N/A | J267: ='Raw data'!K187 -> 0 | K267: ='Raw data'!H187 -> 0 | L267: =J267*K267 -> 0
...

Sheet Summary(수주업로드용)
H1: =SUBTOTAL(9,H3:H428) -> 194 | J1: =SUBTOTAL(9,J3:J414) -> 686534 | L1: 17128 | P1: af1 더마
A2: Sum Code | B2: 발주코드 | D2: 배송코드 | F2: 상품코드 | H2: UNIT수량 | I2: UNIT단가 | J2: Total Amount | K2: =VLOOKUP(F2,'SUM(히아풀젤,폼 아이캐쳐붙인걸로)'!A:E,5,0) -> #N/A | L2: 오늘재고
A3: =D3&F3 -> 81010902ME90621NA7 | B3: 81010000 | D3: 81010902 | E3: 시화물류센터 | F3: ME90621NA7 | H3: =SUMIF('서식(직납)'!B:L,'Summary(수주업로드용)'!A3,'서식(직납)'!J:J) -> 6 | I3: =IF(H3="0","0",VLOOKUP(A3,'서식(직납)'!B:K,10,0)) -> 4469 | J3: =H3*I3 -> 26814 | K3: =VLOOKUP(F3,'SUM(히아풀젤,폼 아이캐쳐붙인걸로)'!A:E,5,0) -> 0 | M3: =VLOOKUP(F3,제품명!$D:$E,2,0) -> (new)아크네스 클리어 앤 화이트 포밍 워시 150ml 1+1
A4: =D4&F4 -> 81010902ME90621AT3 | B4: 81010000 | D4: 81010902 | E4: 시화물류센터 | F4: ME90621AT3 | H4: =SUMIF('서식(직납)'!B:L,'Summary(수주업로드용)'!A4,'서식(직납)'!J:J) -> 0 | I4: =IF(H4="0","0",VLOOKUP(A4,'서식(직납)'!B:K,10,0)) -> #N/A | J4: =H4*I4 -> #N/A | K4: =VLOOKUP(F4,'SUM(히아풀젤,폼 아이캐쳐붙인걸로)'!A:E,4,0) -> #N/A | M4: 히아풀 수딩 젤&수딩 폼
A5: =D5&F5 -> 81010902ME90621A07 | B5: 81010000 | D5: 81010902 | E5: 시화물류센터 | F5: ME90621A07 | H5: =SUMIF('서식(직납)'!B:L,'Summary(수주업로드용)'!A5,'서식(직납)'!J:J) -> 0 | I5: =IF(H5="0","0",VLOOKUP(A5,'서식(직납)'!B:K,10,0)) -> #N/A | J5: =H5*I5 -> #N/A | K5: =VLOOKUP(F5,'SUM(히아풀젤,폼 아이캐쳐붙인걸로)'!A:E,4,0) -> #N/A | M5: 무조건 E로 붙여진거 출고할것 !!!!
A6: =D6&F6 -> 81010902ME90621ADI | B6: 81010000 | D6: 81010902 | E6: 시화물류센터 | F6: ME90621ADI | H6: =SUMIF('서식(직납)'!B:L,'Summary(수주업로드용)'!A6,'서식(직납)'!J:J) -> 0 | I6: =IF(H6="0","0",VLOOKUP(A6,'서식(직납)'!B:K,10,0)) -> #N/A | J6: =H6*I6 -> #N/A | K6: =VLOOKUP(F6,'SUM(히아풀젤,폼 아이캐쳐붙인걸로)'!A:E,5,0) -> 0 | M6: =VLOOKUP(F6,제품명!$D:$E,2,0) -> (new)아크네스 데일리 딥 클렌저 100g (6입)
A7: =D7&F7 -> 81010902ME90621A04 | B7: 81010000 | D7: 81010902 | E7: 시화물류센터 | F7: ME90621A04 | H7: =SUMIF('서식(직납)'!B:L,'Summary(수주업로드용)'!A7,'서식(직납)'!J:J) -> 0 | I7: =IF(H7="0","0",VLOOKUP(A7,'서식(직납)'!B:K,10,0)) -> #N/A | J7: =H7*I7 -> #N/A | K7: =VLOOKUP(F7,'SUM(히아풀젤,폼 아이캐쳐붙인걸로)'!A:E,4,0) -> #N/A
A8: =D8&F8 -> 81010902ME90621A02 | B8: 81010000 | D8: 81010902 | E8: 시화물류센터 | F8: ME90621A02 | H8: =SUMIF('서식(직납)'!B:L,'Summary(수주업로드용)'!A8,'서식(직납)'!J:J) -> 0 | I8: =IF(H8="0","0",VLOOKUP(A8,'서식(직납)'!B:K,10,0)) -> #N/A | J8: =H8*I8 -> #N/A | K8: =VLOOKUP(F8,'SUM(히아풀젤,폼 아이캐쳐붙인걸로)'!A:E,5,0) -> #N/A
A9: =D9&F9 -> 81010902ME90621AFE | B9: 81010000 | D9: 81010902 | E9: 시화물류센터 | F9: ME90621AFE | H9: =SUMIF('서식(직납)'!B:L,'Summary(수주업로드용)'!A9,'서식(직납)'!J:J) -> 18 | I9: =IF(H9="0","0",VLOOKUP(A9,'서식(직납)'!B:K,10,0)) -> 4469 | J9: =H9*I9 -> 80442 | M9: =VLOOKUP(F9,제품명!$D:$E,2,0) -> 아크네스 포밍워시 200ml (인케이스)-RRP
A10: =D10&F10 -> 81010902ME00621TC3 | B10: 81010000 | D10: 81010902 | E10: 시화물류센터 | F10: ME00621TC3 | H10: =SUMIF('서식(직납)'!B:L,'Summary(수주업로드용)'!A10,'서식(직납)'!J:J) -> 0 | I10: =IF(H10="0","0",VLOOKUP(A10,'서식(직납)'!B:K,10,0)) -> #N/A | J10: =H10*I10 -> #N/A | K10: =VLOOKUP(F10,'SUM(히아풀젤,폼 아이캐쳐붙인걸로)'!A:E,4,0) -> #N/A
A11: =D11&F11 -> 81010902ME00621AB1 | B11: 81010000 | D11: 81010902 | E11: 시화물류센터 | F11: ME00621AB1 | H11: =SUMIF('서식(직납)'!B:L,'Summary(수주업로드용)'!A11,'서식(직납)'!J:J) -> 0 | I11: =IF(H11="0","0",VLOOKUP(A11,'서식(직납)'!B:K,10,0)) -> #N/A | J11: =H11*I11 -> #N/A | K11: =VLOOKUP(F11,'SUM(히아풀젤,폼 아이캐쳐붙인걸로)'!A:E,5,0) -> #N/A
A12: =D12&F12 -> 81010902ME00621C17 | B12: 81010000 | D12: 81010902 | E12: 시화물류센터 | F12: ME00621C17 | H12: =SUMIF('서식(직납)'!B:L,'Summary(수주업로드용)'!A12,'서식(직납)'!J:J) -> 0 | I12: =IF(H12="0","0",VLOOKUP(A12,'서식(직납)'!B:K,10,0)) -> #N/A | J12: =H12*I12 -> #N/A | K12: =VLOOKUP(F12,'SUM(히아풀젤,폼 아이캐쳐붙인걸로)'!A:E,5,0) -> #N/A
A13: =D13&F13 -> 81010902ME00621AT6 | B13: 81010000 | D13: 81010902 | E13: 시화물류센터 | F13: ME00621AT6 | H13: =SUMIF('서식(직납)'!B:L,'Summary(수주업로드용)'!A13,'서식(직납)'!J:J) -> 0 | I13: =IF(H13="0","0",VLOOKUP(A13,'서식(직납)'!B:K,10,0)) -> #N/A | J13: =H13*I13 -> #N/A
A14: =D14&F14 -> 81010902ME00621AM1 | B14: 81010000 | D14: 81010902 | E14: 시화물류센터 | F14: ME00621AM1 | H14: =SUMIF('서식(직납)'!B:L,'Summary(수주업로드용)'!A14,'서식(직납)'!J:J) -> 0 | I14: =IF(H14="0","0",VLOOKUP(A14,'서식(직납)'!B:K,10,0)) -> #N/A | J14: =H14*I14 -> #N/A
A15: =D15&F15 -> 81010902ME00621AS1 | B15: 81010000 | D15: 81010902 | E15: 시화물류센터 | F15: ME00621AS1 | H15: =SUMIF('서식(직납)'!B:L,'Summary(수주업로드용)'!A15,'서식(직납)'!J:J) -> 0 | I15: =IF(H15="0","0",VLOOKUP(A15,'서식(직납)'!B:K,10,0)) -> #N/A | J15: =H15*I15 -> #N/A | K15: =VLOOKUP(F15,'SUM(히아풀젤,폼 아이캐쳐붙인걸로)'!A:E,4,0) -> #N/A
A16: =D16&F16 -> 81010902ME00621AR1 | B16: 81010000 | D16: 81010902 | E16: 시화물류센터 | F16: ME00621AR1 | H16: =SUMIF('서식(직납)'!B:L,'Summary(수주업로드용)'!A16,'서식(직납)'!J:J) -> 0 | I16: =IF(H16="0","0",VLOOKUP(A16,'서식(직납)'!B:K,10,0)) -> #N/A | J16: =H16*I16 -> #N/A | K16: =VLOOKUP(F16,'SUM(히아풀젤,폼 아이캐쳐붙인걸로)'!A:E,4,0) -> #N/A
A17: =D17&F17 -> 81010902ME00621AL1 | B17: 81010000 | D17: 81010902 | E17: 시화물류센터 | F17: ME00621AL1 | H17: =SUMIF('서식(직납)'!B:L,'Summary(수주업로드용)'!A17,'서식(직납)'!J:J) -> 0 | I17: =IF(H17="0","0",VLOOKUP(A17,'서식(직납)'!B:K,10,0)) -> #N/A | J17: =H17*I17 -> #N/A | K17: =VLOOKUP(F17,'SUM(히아풀젤,폼 아이캐쳐붙인걸로)'!A:E,4,0) -> #N/A
A18: =D18&F18 -> 81010902ME00621AG1 | B18: 81010000 | D18: 81010902 | E18: 시화물류센터 | F18: ME00621AG1 | H18: =SUMIF('서식(직납)'!B:L,'Summary(수주업로드용)'!A18,'서식(직납)'!J:J) -> 0 | I18: =IF(H18="0","0",VLOOKUP(A18,'서식(직납)'!B:K,10,0)) -> #N/A | J18: =H18*I18 -> #N/A | K18: =VLOOKUP(F18,'SUM(히아풀젤,폼 아이캐쳐붙인걸로)'!A:E,4,0) -> #N/A
A19: =D19&F19 -> 81010902ME00621AF9 | B19: 81010000 | D19: 81010902 | E19: 시화물류센터 | F19: ME00621AF9 | H19: =SUMIF('서식(직납)'!B:L,'Summary(수주업로드용)'!A19,'서식(직납)'!J:J) -> 0 | I19: =IF(H19="0","0",VLOOKUP(A19,'서식(직납)'!B:K,10,0)) -> #N/A | J19: =H19*I19 -> #N/A | K19: =VLOOKUP(F19,'SUM(히아풀젤,폼 아이캐쳐붙인걸로)'!A:E,5,0) -> #N/A | M19: =VLOOKUP(F19,제품명!$D:$E,2,0) -> 아크네스 더마 릴리프 모이스처 폼클렌저
A20: =D20&F20 -> 81010902ME00621A08 | B20: 81010000 | D20: 81010902 | E20: 시화물류센터 | F20: ME00621A08 | H20: =SUMIF('서식(직납)'!B:L,'Summary(수주업로드용)'!A20,'서식(직납)'!J:J) -> 0 | I20: =IF(H20="0","0",VLOOKUP(A20,'서식(직납)'!B:K,10,0)) -> #N/A | J20: =H20*I20 -> #N/A | K20: =VLOOKUP(F20,'SUM(히아풀젤,폼 아이캐쳐붙인걸로)'!A:E,5,0) -> #N/A
A21: =D21&F21 -> 81010902ME90621SM4 | B21: 81010000 | D21: 81010902 | E21: 시화물류센터 | F21: ME90621SM4 | H21: =SUMIF('서식(직납)'!B:L,'Summary(수주업로드용)'!A21,'서식(직납)'!J:J) -> 0 | I21: =IF(H21="0","0",VLOOKUP(A21,'서식(직납)'!B:K,10,0)) -> #N/A | J21: =H21*I21 -> #N/A | K21: =VLOOKUP(F21,'SUM(히아풀젤,폼 아이캐쳐붙인걸로)'!A:E,4,0) -> #N/A
A22: =D22&F22 -> 81010902ME90621SL2 | B22: 81010000 | D22: 81010902 | E22: 시화물류센터 | F22: ME90621SL2 | H22: =SUMIF('서식(직납)'!B:L,'Summary(수주업로드용)'!A22,'서식(직납)'!J:J) -> 0 | I22: =IF(H22="0","0",VLOOKUP(A22,'서식(직납)'!B:K,10,0)) -> #N/A | J22: =H22*I22 -> #N/A | K22: =VLOOKUP(F22,'SUM(히아풀젤,폼 아이캐쳐붙인걸로)'!A:E,4,0) -> #N/A
A23: =D23&F23 -> 81010902ME90621SCM | B23: 81010000 | D23: 81010902 | E23: 시화물류센터 | F23: ME90621SCM | H23: =SUMIF('서식(직납)'!B:L,'Summary(수주업로드용)'!A23,'서식(직납)'!J:J) -> 0 | I23: =IF(H23="0","0",VLOOKUP(A23,'서식(직납)'!B:K,10,0)) -> #N/A | J23: =H23*I23 -> #N/A | K23: =VLOOKUP(F23,'SUM(히아풀젤,폼 아이캐쳐붙인걸로)'!A:E,4,0) -> #N/A
A24: =D24&F24 -> 81010902ME90621KW1 | B24: 81010000 | D24: 81010902 | E24: 시화물류센터 | F24: ME90621KW1 | H24: =SUMIF('서식(직납)'!B:L,'Summary(수주업로드용)'!A24,'서식(직납)'!J:J) -> 0 | I24: =IF(H24="0","0",VLOOKUP(A24,'서식(직납)'!B:K,10,0)) -> #N/A | J24: =H24*I24 -> #N/A | K24: =VLOOKUP(F24,'SUM(히아풀젤,폼 아이캐쳐붙인걸로)'!A:E,4,0) -> #N/A
A25: =D25&F25 -> 81010902ME00621H51 | B25: 81010000 | D25: 81010902 | E25: 시화물류센터 | F25: ME00621H51 | H25: =SUMIF('서식(직납)'!B:L,'Summary(수주업로드용)'!A25,'서식(직납)'!J:J) -> 0 | I25: =IF(H25="0","0",VLOOKUP(A25,'서식(직납)'!B:K,10,0)) -> #N/A | J25: =H25*I25 -> #N/A | K25: =VLOOKUP(F25,'SUM(히아풀젤,폼 아이캐쳐붙인걸로)'!A:E,4,0) -> #N/A
A26: =D26&F26 -> 81010902ME90621GPM | B26: 81010000 | D26: 81010902 | E26: 시화물류센터 | F26: ME90621GPM | H26: =SUMIF('서식(직납)'!B:L,'Summary(수주업로드용)'!A26,'서식(직납)'!J:J) -> 0 | I26: =IF(H26="0","0",VLOOKUP(A26,'서식(직납)'!B:K,10,0)) -> #N/A | J26: =H26*I26 -> #N/A | K26: =VLOOKUP(F26,'SUM(히아풀젤,폼 아이캐쳐붙인걸로)'!A:E,4,0) -> #N/A
A27: =D27&F27 -> 81010902ME90621GPL | B27: 81010000 | D27: 81010902 | E27: 시화물류센터 | F27: ME90621GPL | H27: =SUMIF('서식(직납)'!B:L,'Summary(수주업로드용)'!A27,'서식(직납)'!J:J) -> 0 | I27: =IF(H27="0","0",VLOOKUP(A27,'서식(직납)'!B:K,10,0)) -> #N/A | J27: =H27*I27 -> #N/A | K27: =VLOOKUP(F27,'SUM(히아풀젤,폼 아이캐쳐붙인걸로)'!A:E,4,0) -> #N/A
A28: =D28&F28 -> 81010902ME90621GPJ | B28: 81010000 | D28: 81010902 | E28: 시화물류센터 | F28: ME90621GPJ | H28: =SUMIF('서식(직납)'!B:L,'Summary(수주업로드용)'!A28,'서식(직납)'!J:J) -> 0 | I28: =IF(H28="0","0",VLOOKUP(A28,'서식(직납)'!B:K,10,0)) -> #N/A | J28: =H28*I28 -> #N/A | K28: =VLOOKUP(F28,'SUM(히아풀젤,폼 아이캐쳐붙인걸로)'!A:E,4,0) -> #N/A
A29: =D29&F29 -> 81010902ME90621GO8 | B29: 81010000 | D29: 81010902 | E29: 시화물류센터 | F29: ME90621GO8 | H29: =SUMIF('서식(직납)'!B:L,'Summary(수주업로드용)'!A29,'서식(직납)'!J:J) -> 0 | I29: =IF(H29="0","0",VLOOKUP(A29,'서식(직납)'!B:K,10,0)) -> #N/A | J29: =H29*I29 -> #N/A | M29: =VLOOKUP(F29,제품명!$D:$E,2,0) -> 하다라보 고쿠쥰 오일 클렌징 200ml
A30: =D30&F30 -> 81010902ME90621GM5 | B30: 81010000 | D30: 81010902 | E30: 시화물류센터 | F30: ME90621GM5 | H30: =SUMIF('서식(직납)'!B:L,'Summary(수주업로드용)'!A30,'서식(직납)'!J:J) -> 0 | I30: =IF(H30="0","0",VLOOKUP(A30,'서식(직납)'!B:K,10,0)) -> #N/A | J30: =H30*I30 -> #N/A | K30: =VLOOKUP(F30,'SUM(히아풀젤,폼 아이캐쳐붙인걸로)'!A:E,5,0) -> #N/A
A31: =D31&F31 -> 81010902ME90621GLK | B31: 81010000 | D31: 81010902 | E31: 시화물류센터 | F31: ME90621GLK | H31: =SUMIF('서식(직납)'!B:L,'Summary(수주업로드용)'!A31,'서식(직납)'!J:J) -> 0 | I31: =IF(H31="0","0",VLOOKUP(A31,'서식(직납)'!B:K,10,0)) -> #N/A | J31: =H31*I31 -> #N/A
A32: =D32&F32 -> 81010902ME90621GL6 | B32: 81010000 | D32: 81010902 | E32: 시화물류센터 | F32: ME90621GL6 | H32: =SUMIF('서식(직납)'!B:L,'Summary(수주업로드용)'!A32,'서식(직납)'!J:J) -> 0 | I32: =IF(H32="0","0",VLOOKUP(A32,'서식(직납)'!B:K,10,0)) -> #N/A | J32: =H32*I32 -> #N/A | K32: =VLOOKUP(F32,'SUM(히아풀젤,폼 아이캐쳐붙인걸로)'!A:E,4,0) -> #N/A
A33: =D33&F33 -> 81010902ME90621GHV | B33: 81010000 | D33: 81010902 | E33: 시화물류센터 | F33: ME90621GHV | H33: =SUMIF('서식(직납)'!B:L,'Summary(수주업로드용)'!A33,'서식(직납)'!J:J) -> 0 | I33: =IF(H33="0","0",VLOOKUP(A33,'서식(직납)'!B:K,10,0)) -> #N/A | J33: =H33*I33 -> #N/A | K33: =VLOOKUP(F33,'SUM(히아풀젤,폼 아이캐쳐붙인걸로)'!A:E,5,0) -> #N/A
A34: =D34&F34 -> 81010902ME00621H41 | B34: 81010000 | D34: 81010902 | E34: 시화물류센터 | F34: ME00621H41 | H34: =SUMIF('서식(직납)'!B:L,'Summary(수주업로드용)'!A34,'서식(직납)'!J:J) -> 0 | I34: =IF(H34="0","0",VLOOKUP(A34,'서식(직납)'!B:K,10,0)) -> #N/A | J34: =H34*I34 -> #N/A | K34: =VLOOKUP(F34,'SUM(히아풀젤,폼 아이캐쳐붙인걸로)'!A:E,5,0) -> #N/A
A35: =D35&F35 -> 81010902ME00621CM5 | B35: 81010000 | D35: 81010902 | E35: 시화물류센터 | F35: ME00621CM5 | H35: =SUMIF('서식(직납)'!B:L,'Summary(수주업로드용)'!A35,'서식(직납)'!J:J) -> 0 | I35: =IF(H35="0","0",VLOOKUP(A35,'서식(직납)'!B:K,10,0)) -> #N/A | J35: =H35*I35 -> #N/A | K35: =VLOOKUP(F35,'SUM(히아풀젤,폼 아이캐쳐붙인걸로)'!A:E,5,0) -> 0
A36: =D36&F36 -> 81010902ME90621GE1 | B36: 81010000 | D36: 81010902 | E36: 시화물류센터 | F36: ME90621GE1 | H36: =SUMIF('서식(직납)'!B:L,'Summary(수주업로드용)'!A36,'서식(직납)'!J:J) -> 0 | I36: =IF(H36="0","0",VLOOKUP(A36,'서식(직납)'!B:K,10,0)) -> #N/A | J36: =H36*I36 -> #N/A | K36: =VLOOKUP(F36,'SUM(히아풀젤,폼 아이캐쳐붙인걸로)'!A:E,4,0) -> #N/A
A37: =D37&F37 -> 81010902ME90621GCK | B37: 81010000 | D37: 81010902 | E37: 시화물류센터 | F37: ME90621GCK | H37: =SUMIF('서식(직납)'!B:L,'Summary(수주업로드용)'!A37,'서식(직납)'!J:J) -> 0 | I37: =IF(H37="0","0",VLOOKUP(A37,'서식(직납)'!B:K,10,0)) -> #N/A | J37: =H37*I37 -> #N/A | K37: =VLOOKUP(F37,'SUM(히아풀젤,폼 아이캐쳐붙인걸로)'!A:E,4,0) -> #N/A
A38: =D38&F38 -> 81010902ME00621SS1 | B38: 81010000 | D38: 81010902 | E38: 시화물류센터 | F38: ME00621SS1 | H38: =SUMIF('서식(직납)'!B:L,'Summary(수주업로드용)'!A38,'서식(직납)'!J:J) -> 0 | I38: =IF(H38="0","0",VLOOKUP(A38,'서식(직납)'!B:K,10,0)) -> #N/A | J38: =H38*I38 -> #N/A | K38: =VLOOKUP(F38,'SUM(히아풀젤,폼 아이캐쳐붙인걸로)'!A:E,4,0) -> #N/A
A39: =D39&F39 -> 81010902ME00621GP1 | B39: 81010000 | D39: 81010902 | E39: 시화물류센터 | F39: ME00621GP1 | H39: =SUMIF('서식(직납)'!B:L,'Summary(수주업로드용)'!A39,'서식(직납)'!J:J) -> 0 | I39: =IF(H39="0","0",VLOOKUP(A39,'서식(직납)'!B:K,10,0)) -> #N/A | J39: =H39*I39 -> #N/A | K39: =VLOOKUP(F39,'SUM(히아풀젤,폼 아이캐쳐붙인걸로)'!A:E,4,0) -> #N/A
A40: =D40&F40 -> 81010902ME90521GS2 | B40: 81010000 | D40: 81010902 | E40: 시화물류센터 | F40: ME90521GS2 | H40: =SUMIF('서식(직납)'!B:L,'Summary(수주업로드용)'!A40,'서식(직납)'!J:J) -> 0 | I40: =IF(H40="0","0",VLOOKUP(A40,'서식(직납)'!B:K,10,0)) -> #N/A | J40: =H40*I40 -> #N/A | K40: =VLOOKUP(F40,'SUM(히아풀젤,폼 아이캐쳐붙인걸로)'!A:E,5,0) -> 0 | M40: =VLOOKUP(F40,제품명!$D:$E,2,0) -> 립아이스 립밤 스트로베리 (2021) (12입)
...

Sheet 제품명
A1: BRAND | B1: 이마트 상품명 | C1: 바코드 | D1: 상품코드(기획) | E1: 상품명(기획) | F1: 원래코드 | G1: 비고 | H1: REGUAL | I1: PROMOTION PRICE
A2: Acnes | B2: 아크네스 클리어앤화이트 포밍워시 150g | C2: 8809020346585 | D2: ME90621NA7 | E2: (new)아크네스 클리어 앤 화이트 포밍 워시 150ml 1+1 | F2: ME90621A05 | G2: 6/3 잠시만 출고 | H2: 6975
A3: Acnes | B3: 아크네스 오일컨트롤 스킨 120ml | C3: 8809020346523 | D3: ME90621AT3 | E3: 아크네스 오일 컨트롤 파우더 스킨 120ml (인케이스)-RRP | F3: ME90621AT3 | G3: 파우더스킨+코팩+필름 : 할당량 소진시까지 | H3: 6510
A4: Acnes | B4: 아크네스 클리어앤화이트 크리미워시 100g | C4: 8809020346660 | D4: ME90621A07 | E4: 아크네스 클리어앤화이트 크리미워시 100g | F4: ME90621A07
A5: Acnes | B5: 아크네스 데일리 딥클렌저 100g | C5: 8809020346592 | D5: ME90621ADI | E5: (new)아크네스 데일리 딥 클렌저 100g (6입) | F5: ME90621A06 | G5: ME90621DF7 | H5: 2021년 12월 디자인변경으로 코드변경
A6: Acnes | B6: 아크네스 크리미워시130g | C6: 8809020346516 | D6: ME90621A02 | E6: 아크네스 크리미 워시 130g (인케이스)-RRP | F6: ME00621P78 | G6: 잠시 테스코 재고 사용 | H6: 6510
A7: Acnes | B7: 아크네스 포밍워시 200ml | C7: 8809020346509 | D7: ME90621AFE | E7: 아크네스 포밍워시 200ml (인케이스)-RRP | F7: ME90621A01 | H7: 6975
A8: Acnes | B8: 아크네스 타겟 리페어 크림 | C8: 8809020340255 | D8: ME00621TC3 | E8: 아크네스 타겟 리페어 크림
A9: Acnes | B9: 아크네스 세범 밸런싱 스킨 180ml | C9: 8809020340286 | D9: ME00621AB1 | E9: 아크네스 세범 밸런싱 스킨+크림샤쉐2장 (6입) | F9: ME00621AB1 | H9: 홈플러스 기획 출고중
A10: Acnes | B10: 아크네스 미셀라 클렌징워터 | C10: 8809020340262 | D10: ME00621C17 | E10: 아크네스 미셀라 클렌징워터 | F10: ME00621MW2
A11: Acnes | B11: 아크네스 스팟클리어젤18g | C11: 8809020346561 | D11: ME00621AT6 | E11: 아크네스 스팟 클리어 젤 18g (인케이스)-RRP | F11: ME00621AT6 | G11: 스팟 클리어젤+코팩+필름 : 할당량 소진시까지 | H11: 6975
A12: Acnes | B12: 아크네스 모이스처 로션 150ml | C12: 8809020340293 | D12: ME00621AM1 | E12: 아크네스 모이스처 로션 150ml | F12: ME00621AM1 | G12: 모이스처로션+코팩+필름 : 할당량 소진시까지 | H12: 홈플러스 기획 출고중
A13: Acnes | B13: 아크네스 더마 릴리프 밸런싱스킨 | C13: #N/A | D13: ME00621AS1 | E13: 아크네스 더마 릴리프 밸런싱 스킨 200ml 6 | F13: ME00621AS1 | H13: 8237
A14: Acnes | B14: 아크네스 더마 릴리프 리커버리 크림 | C14: #N/A | D14: ME00621AR1 | E14: 아크네스 더마 릴리프 리커버리 크림 40ml | F14: ME00621AR1 | H14: 11326
A15: Acnes | B15: 아크네스 더마 릴리프 에센스로션 | C15: #N/A | D15: ME00621AL1 | E15: 아크네스 더마 릴리프 에센스 로션80ml 6입 | F15: ME00621AL1 | H15: 9267
A16: Acnes | B16: 아크네스 더마 릴리프 밸런싱 젤클렌저 | C16: #N/A | D16: ME00621AG1 | E16: 아크네스 더마 릴리프 퓨리파잉 젤클렌저 2 | F16: ME00621AG1 | H16: 7722
A17: Acnes | B17: 아크네스 더마 릴리프 모이스처 폼클렌저 | C17: 8809020349722 | D17: ME00621AF9 | E17: 아크네스 더마 릴리프 모이스처 폼클렌저 | F17: ME00621AF9 | G17: 6/3 잠시만 출고 | H17: 7722
A18: Acnes | B18: 아크네스 모이스처크림 50ml | C18: 8809020349425 | D18: ME00621A08 | E18: 아크네스 모이스처 크림+스팟 젤미니 (36입 | F18: ME00621A08 | H18: 9299
A19: HADA | B19: 시로쥰밀크 140ml | C19: 8809020349104 | D19: ME90621SM6 | E19: 하다라보 시로쥰 밀크 140ml | F19: ME90621SM4
A20: HADA | B20: 시로쥰로션 170ml | C20: 8809020349098 | D20: ME90621SL2 | E20: 하다라보 시로쥰 로션 170ml | F20: ME90621SLO
A21: HADA | B21: 시로쥰 크림 50g | C21: 8809020349210 | D21: ME90621SCM | E21: 하다라보 시로쥰 크림 50g | F21: ME90621SCM
A22: HADA | B22: 하다라보 기와미츠 로즈워터 구버전+화장솜기획(6입) | C22: 8809020349371 | D22: ME00621H51 | E22: 하다라보 기와미츠 로즈워터 구버전+화장솜기획(6입) | G22: 8809020349418 | H22: 11862
A23: HADA | B23: 하다라보 기와미츠 하토무기 비타민C구버전+화장솜기획(6입) | C23: 8809020349388 | D23: ME90621GHV | E23: 하다라보 기와미츠 하토무기 비타민C구버전+화장솜기획(6입)
A24: HADA | B24: 하다라보 기와미츠 워터+화장솜 기획 (6입) | C24: 8809020349418 | D24: ME90621KW1 | E24: 하다라보 기와미츠 워터+화장솜 기획 (6입) | G24: 8809020349388 | H24: 11862
A25: HADA | B25: 하다라보 고쿠쥰 프리미엄 밀크 | C25: 8809020349784 | D25: ME90621GPM | E25: 하다라보 고쿠쥰 프리미엄 밀크
A26: HADA | B26: 하다라보 고쿠쥰 프리미엄 로션 | C26: 8809020349777 | D26: ME90621GP4 | E26: 하다라보 고쿠쥰 프리미엄 로션 170ml (6입)-NF
A27: HADA | B27: 하다라보 고쿠쥰 프리미엄 오일젤리 | C27: 8809020349791 | D27: ME90621GPJ | E27: 하다라보 고쿠쥰 프리미엄 오일젤리
A28: HADA | B28: 코쿠준오일클렌징200ml | C28: 8809020349166 | D28: ME90621GO8 | E28: 하다라보 고쿠쥰 오일 클렌징 200ml | F28: ME90621GO5 | H28: 10057 | I28: 2021-03-24부터 신형(12입)으로 납품
A29: HADA | B29: 고쿠쥰밀크140ml | C29: 8809020349067 | D29: ME90621GM5 | E29: 하다라보 고쿠쥰 밀크 140ml | F29: ME90621GM5 | H29: 11346
A30: HADA | B30: 고쿠쥰로션170ml | C30: 8809020349050 | D30: ME90621GLK | E30: 하다라보 고쿠쥰 로션 170ml | F30: ME90621GLK | H30: 11346
A31: HADA | B31: 하다라보 고쿠쥰 로션 라이트 | C31: 8809020349906 | D31: ME90621GL6 | E31: 하다라보 고쿠쥰 로션 라이트
A32: HADA | B32: 고쿠쥰 포밍 워시 160ml | C32: 8809020349968 | D32: ME00621H41 | E32: 고쿠쥰 포밍 워시 160ml | F32: ME90621HGW | G32: ME90621H41
A33: HADA | B33: 고쿠쥰훼이스워시100g | C33: 8809020349036 | D33: ME00621CM5 | E33: 하다라보 고쿠쥰 훼이스 워시 100g | F33: ME00621CM5 | H33: 7220
A34: HADA | B34: 고쿠쥰에센스30g | C34: 8809020349074 | D34: ME90621GE1 | E34: 하다라보 고쿠쥰 에센스 30g | F34: ME90621GES
A35: HADA | B35: 고쿠쥰 크림 50g | C35: 8809020349203 | D35: ME90621GCK | E35: 하다라보 고쿠쥰 크림 50g | F35: ME90621GCM
A36: HADA | B36: 시로쥰로션밀크세트 | C36: 8809020349142 | D36: ME00621SS1 | E36: 하다라보 시로쥰 로션 & 밀크 세트 | F36: ME00621SP1
A37: HADA | B37: 고쿠쥰로션밀크세트170ml/140ml | C37: 8809020349135 | D37: ME00621GP1 | E37: 하다라보 고쿠쥰 로션 & 밀크 세트 | F37: ME00621GP1
C38: 8809020349944 | D38: ME90621FG1 | E38: 하다라보 고쿠쥰 퍼펙트젤 100g N-design
A39: Lipcare | B39: 립케어립아이스딸기3.5g | C39: 8809020342419 | D39: ME90521CLS | E39: 립아이스 딸기 X 라인 | F39: 2021년 종료 | G39: 12
A40: Lipcare | B40: 립케어 립아이스레몬 | C40: 8809020342211 | D40: ME90521CLL | E40: 립아이스 레몬 X 라인 | F40: 2021년 종료 | G40: 12
...

Sheet 점포코드 
A2: 점포명 | B2: 점포코드 | E2: 81010000 | F2: 이마트 본점
A3: 이마트 김해터미널점 | B3: 81010928
A4: 김해점 | B4: 81010928
A5: 창동점 | B5: 81010001 | C5: 81010001 | E5: 81010001 | F5: 이마트 창동점
A6: 시화(D)_BNS | B6: 81010902
A7: 일산점 | B7: 81010002 | C7: 81010002 | D7: d | E7: 81010002 | F7: 이마트 일산점 | G7: ㅊ
A8: 안산점 | B8: 81010003 | E8: 81010003 | F8: 이마트 안산점
A9: 부평점 | B9: 81010004 | E9: 81010004 | F9: 이마트 부평점
A10: 제주점 | B10: 81010005 | C10: 81010005 | E10: 81010005 | F10: 이마트 제주점
A11: 분당점 | B11: 81010006 | C11: 81010006 | E11: 81010006 | F11: 이마트 분당점
A12: 남원점 | B12: 81010007 | E12: 81010007 | F12: 이마트 남원점
A13: 안양점 | B13: 81010008 | C13: 81010008 | E13: 81010008 | F13: 이마트 안양점
A14: 서부산점 | B14: 81010009 | E14: 81010009 | F14: 이마트 서부산점
A15: 김천점 | B15: 81010010 | C15: 81010010 | E15: 81010010 | F15: 이마트 김천점
A16: 동광주점 | B16: 81010011 | E16: 81010011 | F16: 이마트 동광주점
A17: 청주점 | B17: 81010012 | C17: 81010012 | E17: 81010012 | F17: 이마트 청주점
A18: 전주점 | B18: 81010138 | C18: 81010138 | E18: 81010013 | F18: 이마트 전주점
A19: 부천점 | B19: 81010014 | C19: 81010014 | E19: 81010014 | F19: 이마트 부천점
A20: 원주점 | B20: 81010015 | C20: 81010015 | E20: 81010015 | F20: 이마트 원주점
A21: 구로점 | B21: 81010016 | C21: 81010016 | E21: 81010016 | F21: 이마트 구로점
A22: 신월점 | B22: 81010017 | E22: 81010017 | F22: 이마트 신월점
A23: 성서점 | B23: 81010018 | C23: 81010018 | E23: 81010018 | F23: 이마트 성서점
A24: 산본점 | B24: 81010019 | C24: 81010019 | E24: 81010019 | F24: 이마트 산본점
A25: 천호점 | B25: 81010020 | C25: 81010020 | E25: 81010020 | F25: 이마트 천호점
A26: 가양점 | B26: 81010021 | C26: 81010021 | E26: 81010021 | F26: 이마트 가양점
A27: 해운대점 | B27: 81010022 | C27: 81010022 | E27: 81010022 | F27: 이마트 해운대점
A28: 시화점 | B28: 81010023 | C28: 81010023 | E28: 81010023 | F28: 이마트 시화점
A29: 상봉점 | B29: 81010024 | C29: 81010024 | E29: 81010024 | F29: 이마트 상봉점
A30: 이천점 | B30: 81010025 | C30: 81010025 | E30: 81010025 | F30: 이마트 이천점
A31: 진주점 | B31: 81010026 | C31: 81010026 | E31: 81010026 | F31: 이마트 진주점
A32: 목포점 | B32: 81010027 | C32: 81010027 | E32: 81010027 | F32: 이마트 목포점
A33: 동인천점 | B33: 81010028 | C33: 81010028 | E33: 81010028 | F33: 이마트 동인천점
A34: 만촌점 | B34: 81010029 | C34: 81010029 | E34: 81010029 | F34: 이마트 만촌점
... A37: 월배점 | B37: 81010032 | C37: 81010032 | E37: 81010032 | F37: 이마트 월배점
A38: 수서점 | B38: 81010034 | E38: 81010034 | F38: 이마트 수서점
A39: 상무점 | B39: 81010035 | E39: 81010035 | F39: 이마트 광주상무점
A40: 수원점 | B40: 81010036 | C40: 81010036 | E40: 81010036 | F40: 이마트 수원점
A41: 충주점 | B41: 81010037 | C41: 81010037 | E41: 81010037 | F41: 이마트 충주점
A42: 평택점 | B42: 81010038 | C42: 81010038 | E42: 81010038 | F42: 이마트 평택점
A43: 은평점 | B43: 81010039 | C43: 81010039 | E43: 81010039 | F43: 이마트 은평점
...

Sheet Sheet1
A3: 행 레이블 | B3: 합계 : 환산
A4: ME00421150 | B4: 25977
A5: ME00421151 | B5: 86
A6: ME00421153 | B6: 6959
A7: ME00421180 | B7: 30
A8: ME00421185 | B8: 16393
A9: ME00421186 | B9: 2560
A10: ME0042118C | B10: 758
A11: ME0042118N | B11: 45904
A12: ME0042118S | B12: 2172
A13: ME00421200 | B13: 28291
A14: ME00421300 | B14: 9962
A15: ME00421301 | B15: 424
... A284: 총합계 | B284: 4569074
